Workbook

Sheet RegisteredPlayers
A1: Registered
A3: #PYYPCLCJ | B3: danceshell12 | F3: {=A3:B17} | G3: danceshell12
A4: #89Q2YQ9C | B4: zeon | F4: #89Q2YQ9C | G4: zeon
A5: #2PV8PYC0Q | B5: Bunny | F5: #2PV8PYC0Q | G5: Bunny
A6: #CVYUC2CJ | B6: vAtS | F6: #CVYUC2CJ | G6: vAtS
A7: #LGP2P0CRV | B7: babÿ champagne | F7: #LGP2P0CRV | G7: babÿ champagne
A8: #2GQLPJ9JL | B8: TDC | F8: #2GQLPJ9JL | G8: TDC
A9: #URGR20J0 | B9: zeezus | F9: #URGR20J0 | G9: zeezus
A10: #29G0L9JL9 | B10: Jesús F7 | F10: #29G0L9JL9 | G10: Jesús F7
A11: #JJ8Y9JU8 | B11: champagnebucci | F11: #JJ8Y9JU8 | G11: champagnebucci
A12: #Y0RVYJVC | B12: ⚡️⚡️ G U S ⚡️⚡️ | F12: #Y0RVYJVC | G12: ⚡️⚡️ G U S ⚡️⚡️
A13: #YCVR9CC0C | B13: Bilbo_Swaggins | F13: #YCVR9CC0C | G13: Bilbo_Swaggins
A14: #8JU98908G | B14: H@PP¥ | F14: #8JU98908G | G14: H@PP¥
A15: #P920JLC0P | B15: EE Sp∆ce | F15: #P920JLC0P | G15: EE Sp∆ce
... A17: #9RCCUY28U | B17: Roman Rittik | F17: #9RCCUY28U | G17: Roman Rittik

Sheet Rankings_Old
B1: Jan | C1: Feb | D1: Mar | E1: Apr | F1: May | G1: Jun | H1: Jul | I1: Aug | J1: Sep | K1: Oct | L1: Nov | M1: Dec | N1: Total % | O1: Total stars | P1: Rank | Q1: 100*total%
A2: Player
A3: H@PPY | B3: 21 | C3: 0 | D3: 0 | E3: 0 | F3: 0 | G3: 0 | H3: 0 | I3: 0 | J3: 0 | K3: 0 | L3: 0 | M3: 0 | N3: 7 | O3: 21 | P3: 19 | Q3: =100*N3
A4: Bilbo_Swaggins | B4: 19 | C4: 17 | D4: 17 | E4: 7 | F4: 0 | G4: 0 | H4: 0 | I4: 0 | J4: 0 | K4: 0 | L4: 0 | M4: 0 | N4: 23.08 | O4: 60 | P4: 4 | Q4: =100*N4
A5: TDC | B5: 19 | C5: 11 | D5: 9 | E5: 15 | F5: 0 | G5: 0 | H5: 0 | I5: 0 | J5: 0 | K5: 0 | L5: 0 | M5: 0 | N5: 20.24 | O5: 54 | P5: 6 | Q5: =100*N5
A6: Dr. Shivam | B6: 18 | C6: 16 | D6: 16 | E6: 13 | F6: 0 | G6: 0 | H6: 0 | I6: 0 | J6: 0 | K6: 0 | L6: 0 | M6: 0 | N6: 23.24 | O6: 63 | P6: 3 | Q6: =100*N6
A7: champagnebucci | B7: 17 | C7: 16 | D7: 17 | E7: 16 | F7: 0 | G7: 0 | H7: 0 | I7: 0 | J7: 0 | K7: 0 | L7: 0 | M7: 0 | N7: 25.24 | O7: 66 | P7: 2 | Q7: =100*N7
A8: paul | B8: 17 | C8: 10 | D8: 6 | E8: 0 | F8: 0 | G8: 0 | H8: 0 | I8: 0 | J8: 0 | K8: 0 | L8: 0 | M8: 0 | N8: 14.53 | O8: 33 | P8: 13 | Q8: =100*N8
A9: Voltage-Gamer | B9: 17 | C9: 0 | D9: 0 | E9: 12 | F9: 0 | G9: 0 | H9: 0 | I9: 0 | J9: 0 | K9: 0 | L9: 0 | M9: 0 | N9: 10.29 | O9: 29 | P9: 16 | Q9: =100*N9
A10: EE Gus | B10: 16 | C10: 0 | D10: 0 | E10: 0 | F10: 0 | G10: 0 | H10: 0 | I10: 0 | J10: 0 | K10: 0 | L10: 0 | M10: 0 | N10: 6.59 | O10: 16 | P10: 24 | Q10: =100*N10
A11: DD | B11: 16 | C11: 10 | D11: 14 | E11: 0 | F11: 0 | G11: 0 | H11: 0 | I11: 0 | J11: 0 | K11: 0 | L11: 0 | M11: 0 | N11: 15.48 | O11: 40 | P11: 9 | Q11: =100*N11
A12: Dpk GarG Sharma | B12: 16 | C12: 0 | D12: 0 | E12: 0 | F12: 0 | G12: 0 | H12: 0 | I12: 0 | J12: 0 | K12: 0 | L12: 0 | M12: 0 | N12: 5.81 | O12: 16 | P12: 26 | Q12: =100*N12
A13: Jesús F7 | B13: 15 | C13: 14 | D13: 9 | E13: 11 | F13: 0 | G13: 0 | H13: 0 | I13: 0 | J13: 0 | K13: 0 | L13: 0 | M13: 0 | N13: 18.89 | O13: 49 | P13: 7 | Q13: =100*N13
A14: zeezus | B14: 15 | C14: 12 | D14: 16 | E14: 15 | F14: 0 | G14: 0 | H14: 0 | I14: 0 | J14: 0 | K14: 0 | L14: 0 | M14: 0 | N14: 22.8 | O14: 58 | P14: 5 | Q14: =100*N14
... A18: Chris | B18: 10 | C18: 0 | D18: 0 | E18: 0 | F18: 0 | G18: 0 | H18: 0 | I18: 0 | J18: 0 | K18: 0 | L18: 0 | M18: 0 | N18: 4.48 | O18: 10 | P18: 36 | Q18: =100*N18
A19: 0 | B19: 0 | C19: 0 | D19: 0 | E19: 0 | F19: 0 | G19: 0 | H19: 0 | I19: 0 | J19: 0 | K19: 0 | L19: 0 | M19: 0 | N19: 0 | O19: 0 | P19: 39 | Q19: =100*N19
A20: Declan Nice | B20: 20 | C20: 0 | D20: 0 | E20: 0 | F20: 0 | G20: 0 | H20: 0 | I20: 0 | J20: 0 | K20: 0 | L20: 0 | M20: 0 | N20: 6.96 | O20: 20 | P20: 20 | Q20: =100*N20
A21: Vats | B21: 18 | C21: 14 | D21: 20 | E21: 16 | F21: 0 | G21: 0 | H21: 0 | I21: 0 | J21: 0 | K21: 0 | L21: 0 | M21: 0 | N21: 23.75 | O21: 68 | P21: 1 | Q21: =100*N21
A22: baby champagne | B22: 11 | C22: 19 | D22: 0 | E22: 0 | F22: 0 | G22: 0 | H22: 0 | I22: 0 | J22: 0 | K22: 0 | L22: 0 | M22: 0 | N22: 9.69 | O22: 30 | P22: 14 | Q22: =100*N22
A23: 0 | B23: 0 | C23: 0 | D23: 0 | E23: 0 | F23: 0 | G23: 0 | H23: 0 | I23: 0 | J23: 0 | K23: 0 | L23: 0 | M23: 0 | N23: 0 | O23: 0 | P23: 39 | Q23: =100*N23
A24: Rebel | B24: 0 | C24: 15 | D24: 0 | E24: 0 | F24: 0 | G24: 0 | H24: 0 | I24: 0 | J24: 0 | K24: 0 | L24: 0 | M24: 0 | N24: 6.28 | O24: 15 | P24: 27 | Q24: =100*N24
A25: EE Sp∆ce | B25: 0 | C25: 12 | D25: 9 | E25: 15 | F25: 0 | G25: 0 | H25: 0 | I25: 0 | J25: 0 | K25: 0 | L25: 0 | M25: 0 | N25: 14.77 | O25: 36 | P25: 11 | Q25: =100*N25
A26: Roman Rittik | B26: 0 | C26: 12 | D26: 12 | E26: 14 | F26: 0 | G26: 0 | H26: 0 | I26: 0 | J26: 0 | K26: 0 | L26: 0 | M26: 0 | N26: 14.6 | O26: 38 | P26: 10 | Q26: =100*N26
A27: Sp∆ce | B27: 0 | C27: 11 | D27: 8 | E27: 17 | F27: 0 | G27: 0 | H27: 0 | I27: 0 | J27: 0 | K27: 0 | L27: 0 | M27: 0 | N27: 14.38 | O27: 36 | P27: 12 | Q27: =100*N27
A28: Lvl.15⛺️BoBo⛺️ | B28: 0 | C28: 10 | D28: 0 | E28: 0 | F28: 0 | G28: 0 | H28: 0 | I28: 0 | J28: 0 | K28: 0 | L28: 0 | M28: 0 | N28: 4.38 | O28: 10 | P28: 37 | Q28: =100*N28
A29: IaIoberry | B29: 0 | C29: 10 | D29: 0 | E29: 0 | F29: 0 | G29: 0 | H29: 0 | I29: 0 | J29: 0 | K29: 0 | L29: 0 | M29: 0 | N29: 4.22 | O29: 10 | P29: 38 | Q29: =100*N29
A30: Crispy | B30: 0 | C30: 10 | D30: 13 | E30: 0 | F30: 0 | G30: 0 | H30: 0 | I30: 0 | J30: 0 | K30: 0 | L30: 0 | M30: 0 | N30: 9.88 | O30: 23 | P30: 18 | Q30: =100*N30
A31: EE Paradox | B31: 0 | C31: 0 | D31: 15 | E31: 0 | F31: 0 | G31: 0 | H31: 0 | I31: 0 | J31: 0 | K31: 0 | L31: 0 | M31: 0 | N31: 6.08 | O31: 15 | P31: 28 | Q31: =100*N31
A32: EE Paradox(2) | B32: 0 | C32: 0 | D32: 15 | E32: 0 | F32: 0 | G32: 0 | H32: 0 | I32: 0 | J32: 0 | K32: 0 | L32: 0 | M32: 0 | N32: 5.34 | O32: 15 | P32: 31 | Q32: =100*N32
A33: 火 Pegasus | B33: 0 | C33: 0 | D33: 14 | E33: 0 | F33: 0 | G33: 0 | H33: 0 | I33: 0 | J33: 0 | K33: 0 | L33: 0 | M33: 0 | N33: 5.58 | O33: 14 | P33: 32 | Q33: =100*N33
A34: Tasex | B34: 0 | C34: 0 | D34: 13 | E34: 16 | F34: 0 | G34: 0 | H34: 0 | I34: 0 | J34: 0 | K34: 0 | L34: 0 | M34: 0 | N34: 10.8 | O34: 29 | P34: 15 | Q34: =100*N34
A35: Crusader | B35: 0 | C35: 0 | D35: 12 | E35: 0 | F35: 0 | G35: 0 | H35: 0 | I35: 0 | J35: 0 | K35: 0 | L35: 0 | M35: 0 | N35: 4.4 | O35: 12 | P35: 34 | Q35: =100*N35
... A42: zeon | B42: 0 | C42: 0 | D42: 0 | E42: 18 | F42: 0 | G42: 0 | H42: 0 | I42: 0 | J42: 0 | K42: 0 | L42: 0 | M42: 0 | N42: 6 | O42: 18 | P42: 21 | Q42: =100*N42
A43: 0 | B43: 0 | C43: 0 | D43: 0 | E43: 0 | F43: 0 | G43: 0 | H43: 0 | I43: 0 | J43: 0 | K43: 0 | L43: 0 | M43: 0 | N43: 0 | O43: 0 | P43: 39 | Q43: =100*N43
A44: 0 | B44: 0 | C44: 0 | D44: 0 | E44: 0 | F44: 0 | G44: 0 | H44: 0 | I44: 0 | J44: 0 | K44: 0 | L44: 0 | M44: 0 | N44: 0 | O44: 0 | P44: 39 | Q44: =100*N44
A45: 0 | B45: 0 | C45: 0 | D45: 0 | E45: 0 | F45: 0 | G45: 0 | H45: 0 | I45: 0 | J45: 0 | K45: 0 | L45: 0 | M45: 0 | N45: 0 | O45: 0 | P45: 39 | Q45: =100*N45
A46: 0 | B46: 0 | C46: 0 | D46: 0 | E46: 0 | F46: 0 | G46: 0 | H46: 0 | I46: 0 | J46: 0 | K46: 0 | L46: 0 | M46: 0 | N46: 0 | O46: 0 | P46: 39 | Q46: =100*N46
A47: 0 | B47: 0 | C47: 0 | D47: 0 | E47: 0 | F47: 0 | G47: 0 | H47: 0 | I47: 0 | J47: 0 | K47: 0 | L47: 0 | M47: 0 | N47: 0 | O47: 0 | P47: 39 | Q47: =100*N47
A48: 0 | B48: 0 | C48: 0 | D48: 0 | E48: 0 | F48: 0 | G48: 0 | H48: 0 | I48: 0 | J48: 0 | K48: 0 | L48: 0 | M48: 0 | N48: 0 | O48: 0 | P48: 39 | Q48: =100*N48
A49: 0 | B49: 0 | C49: 0 | D49: 0 | E49: 0 | F49: 0 | G49: 0 | H49: 0 | I49: 0 | J49: 0 | K49: 0 | L49: 0 | M49: 0 | N49: 0 | O49: 0 | P49: 39 | Q49: =100*N49
...

Sheet Rankings
C1: ="01" | D1: ="02" | E1: ="03" | F1: ="04" | G1: ="05" | H1: ="06" | I1: ="07" | J1: ="08" | K1: ="09" | L1: ="10" | M1: ="11" | N1: ="12" | O1: Total Stars | P1: % Destruction | Q1: Rank | S1: Players | T1: ="01" | U1: ="02" | V1: ="03" | W1: ="04" | X1: ="05" | Y1: ="06" | Z1: ="07" | AA1: ="08" | AB1: ="09" | AC1: ="10" | AD1: ="11" | AE1: ="12" | AF1: Total Stars | AG1: % Destruction | AH1: Rank
A2: Tag | B2: Players
A3: {=_xlfn.ANCHORARRAY(RegisteredPlayers!F3)} | B3: danceshell12 | C3: =_xlfn.XLOOKUP($A3,'01'!$G$3:$G$100,'01'!$R$3:$R$100,"-") | D3: =_xlfn.XLOOKUP($A3,'02'!$G$3:$G$100,'02'!$R$3:$R$100,"-") | E3: =_xlfn.XLOOKUP($A3,'03'!$G$3:$G$100,'03'!$R$3:$R$100,"-") | F3: =_xlfn.XLOOKUP($A3,'04'!$G$3:$G$100,'04'!$R$3:$R$100,"-") | G3: =_xlfn.XLOOKUP($A3,'05'!$G$3:$G$100,'05'!$R$3:$R$100,"-") | H3: =_xlfn.XLOOKUP($A3,'06'!$G$3:$G$100,'06'!$R$3:$R$100,"-") | I3: =_xlfn.XLOOKUP($A3,'07'!$G$3:$G$100,'07'!$R$3:$R$100,"-") | J3: =_xlfn.XLOOKUP($A3,'08'!$G$3:$G$100,'08'!$R$3:$R$100,"-") | K3: =_xlfn.XLOOKUP($A3,'09'!$G$3:$G$100,'09'!$R$3:$R$100,"-") | L3: =_xlfn.XLOOKUP($A3,'10'!$G$3:$G$100,'10'!$R$3:$R$100,"-") | M3: =_xlfn.XLOOKUP($A3,'11'!$G$3:$G$100,'11'!$R$3:$R$100,"-") | N3: =_xlfn.XLOOKUP($A3,'12'!$G$3:$G$100,'12'!$R$3:$R$100,"-") | O3: =SUM(C3:N3) | Q3: 1 | S3: {=_xlfn.SORTBY(B3:P500,O3:O500,-1)} | T3: - | U3: - | V3: - | W3: - | X3: - | Y3: - | Z3: - | AA3: - | AB3: - | AC3: - | AD3: - | AE3: - | AF3: 0 | AG3: 0 | AH3: 1
A4: #89Q2YQ9C | B4: zeon | C4: =_xlfn.XLOOKUP($A4,'01'!$G$3:$G$100,'01'!$R$3:$R$100,"-") | D4: =_xlfn.XLOOKUP($A4,'02'!$G$3:$G$100,'02'!$R$3:$R$100,"-") | E4: =_xlfn.XLOOKUP($A4,'03'!$G$3:$G$100,'03'!$R$3:$R$100,"-") | F4: =_xlfn.XLOOKUP($A4,'04'!$G$3:$G$100,'04'!$R$3:$R$100,"-") | G4: =_xlfn.XLOOKUP($A4,'05'!$G$3:$G$100,'05'!$R$3:$R$100,"-") | H4: =_xlfn.XLOOKUP($A4,'06'!$G$3:$G$100,'06'!$R$3:$R$100,"-") | I4: =_xlfn.XLOOKUP($A4,'07'!$G$3:$G$100,'07'!$R$3:$R$100,"-") | J4: =_xlfn.XLOOKUP($A4,'08'!$G$3:$G$100,'08'!$R$3:$R$100,"-") | K4: =_xlfn.XLOOKUP($A4,'09'!$G$3:$G$100,'09'!$R$3:$R$100,"-") | L4: =_xlfn.XLOOKUP($A4,'10'!$G$3:$G$100,'10'!$R$3:$R$100,"-") | M4: =_xlfn.XLOOKUP($A4,'11'!$G$3:$G$100,'11'!$R$3:$R$100,"-") | N4: =_xlfn.XLOOKUP($A4,'12'!$G$3:$G$100,'12'!$R$3:$R$100,"-") | O4: =SUM(C4:N4) | Q4: 2 | S4: zeon | T4: - | U4: - | V4: - | W4: - | X4: - | Y4: - | Z4: - | AA4: - | AB4: - | AC4: - | AD4: - | AE4: - | AF4: 0 | AG4: 0 | AH4: 2
A5: #2PV8PYC0Q | B5: Bunny | C5: =_xlfn.XLOOKUP($A5,'01'!$G$3:$G$100,'01'!$R$3:$R$100,"-") | D5: =_xlfn.XLOOKUP($A5,'02'!$G$3:$G$100,'02'!$R$3:$R$100,"-") | E5: =_xlfn.XLOOKUP($A5,'03'!$G$3:$G$100,'03'!$R$3:$R$100,"-") | F5: =_xlfn.XLOOKUP($A5,'04'!$G$3:$G$100,'04'!$R$3:$R$100,"-") | G5: - | H5: =_xlfn.XLOOKUP($A5,'06'!$G$3:$G$100,'06'!$R$3:$R$100,"-") | I5: =_xlfn.XLOOKUP($A5,'07'!$G$3:$G$100,'07'!$R$3:$R$100,"-") | J5: =_xlfn.XLOOKUP($A5,'08'!$G$3:$G$100,'08'!$R$3:$R$100,"-") | K5: =_xlfn.XLOOKUP($A5,'09'!$G$3:$G$100,'09'!$R$3:$R$100,"-") | L5: =_xlfn.XLOOKUP($A5,'10'!$G$3:$G$100,'10'!$R$3:$R$100,"-") | M5: =_xlfn.XLOOKUP($A5,'11'!$G$3:$G$100,'11'!$R$3:$R$100,"-") | N5: =_xlfn.XLOOKUP($A5,'12'!$G$3:$G$100,'12'!$R$3:$R$100,"-") | O5: =SUM(C5:N5) | Q5: 3 | S5: Bunny | T5: - | U5: - | V5: - | W5: - | X5: - | Y5: - | Z5: - | AA5: - | AB5: - | AC5: - | AD5: - | AE5: - | AF5: 0 | AG5: 0 | AH5: 3
A6: #CVYUC2CJ | B6: vAtS | C6: =_xlfn.XLOOKUP($A6,'01'!$G$3:$G$100,'01'!$R$3:$R$100,"-") | D6: =_xlfn.XLOOKUP($A6,'02'!$G$3:$G$100,'02'!$R$3:$R$100,"-") | E6: =_xlfn.XLOOKUP($A6,'03'!$G$3:$G$100,'03'!$R$3:$R$100,"-") | F6: =_xlfn.XLOOKUP($A6,'04'!$G$3:$G$100,'04'!$R$3:$R$100,"-") | G6: - | H6: =_xlfn.XLOOKUP($A6,'06'!$G$3:$G$100,'06'!$R$3:$R$100,"-") | I6: =_xlfn.XLOOKUP($A6,'07'!$G$3:$G$100,'07'!$R$3:$R$100,"-") | J6: =_xlfn.XLOOKUP($A6,'08'!$G$3:$G$100,'08'!$R$3:$R$100,"-") | K6: =_xlfn.XLOOKUP($A6,'09'!$G$3:$G$100,'09'!$R$3:$R$100,"-") | L6: =_xlfn.XLOOKUP($A6,'10'!$G$3:$G$100,'10'!$R$3:$R$100,"-") | M6: =_xlfn.XLOOKUP($A6,'11'!$G$3:$G$100,'11'!$R$3:$R$100,"-") | N6: =_xlfn.XLOOKUP($A6,'12'!$G$3:$G$100,'12'!$R$3:$R$100,"-") | O6: =SUM(C6:N6) | Q6: 4 | S6: vAtS | T6: - | U6: - | V6: - | W6: - | X6: - | Y6: - | Z6: - | AA6: - | AB6: - | AC6: - | AD6: - | AE6: - | AF6: 0 | AG6: 0 | AH6: 4
A7: #LGP2P0CRV | B7: babÿ champagne | C7: =_xlfn.XLOOKUP($A7,'01'!$G$3:$G$100,'01'!$R$3:$R$100,"-") | D7: =_xlfn.XLOOKUP($A7,'02'!$G$3:$G$100,'02'!$R$3:$R$100,"-") | E7: =_xlfn.XLOOKUP($A7,'03'!$G$3:$G$100,'03'!$R$3:$R$100,"-") | F7: =_xlfn.XLOOKUP($A7,'04'!$G$3:$G$100,'04'!$R$3:$R$100,"-") | G7: - | H7: =_xlfn.XLOOKUP($A7,'06'!$G$3:$G$100,'06'!$R$3:$R$100,"-") | I7: =_xlfn.XLOOKUP($A7,'07'!$G$3:$G$100,'07'!$R$3:$R$100,"-") | J7: =_xlfn.XLOOKUP($A7,'08'!$G$3:$G$100,'08'!$R$3:$R$100,"-") | K7: =_xlfn.XLOOKUP($A7,'09'!$G$3:$G$100,'09'!$R$3:$R$100,"-") | L7: =_xlfn.XLOOKUP($A7,'10'!$G$3:$G$100,'10'!$R$3:$R$100,"-") | M7: =_xlfn.XLOOKUP($A7,'11'!$G$3:$G$100,'11'!$R$3:$R$100,"-") | N7: =_xlfn.XLOOKUP($A7,'12'!$G$3:$G$100,'12'!$R$3:$R$100,"-") | O7: =SUM(C7:N7) | Q7: 5 | S7: babÿ champagne | T7: - | U7: - | V7: - | W7: - | X7: - | Y7: - | Z7: - | AA7: - | AB7: - | AC7: - | AD7: - | AE7: - | AF7: 0 | AG7: 0 | AH7: 5
A8: #2GQLPJ9JL | B8: TDC | C8: =_xlfn.XLOOKUP($A8,'01'!$G$3:$G$100,'01'!$R$3:$R$100,"-") | D8: =_xlfn.XLOOKUP($A8,'02'!$G$3:$G$100,'02'!$R$3:$R$100,"-") | E8: =_xlfn.XLOOKUP($A8,'03'!$G$3:$G$100,'03'!$R$3:$R$100,"-") | F8: =_xlfn.XLOOKUP($A8,'04'!$G$3:$G$100,'04'!$R$3:$R$100,"-") | G8: - | H8: =_xlfn.XLOOKUP($A8,'06'!$G$3:$G$100,'06'!$R$3:$R$100,"-") | I8: =_xlfn.XLOOKUP($A8,'07'!$G$3:$G$100,'07'!$R$3:$R$100,"-") | J8: =_xlfn.XLOOKUP($A8,'08'!$G$3:$G$100,'08'!$R$3:$R$100,"-") | K8: =_xlfn.XLOOKUP($A8,'09'!$G$3:$G$100,'09'!$R$3:$R$100,"-") | L8: =_xlfn.XLOOKUP($A8,'10'!$G$3:$G$100,'10'!$R$3:$R$100,"-") | M8: =_xlfn.XLOOKUP($A8,'11'!$G$3:$G$100,'11'!$R$3:$R$100,"-") | N8: =_xlfn.XLOOKUP($A8,'12'!$G$3:$G$100,'12'!$R$3:$R$100,"-") | O8: =SUM(C8:N8) | Q8: 6 | S8: TDC | T8: - | U8: - | V8: - | W8: - | X8: - | Y8: - | Z8: - | AA8: - | AB8: - | AC8: - | AD8: - | AE8: - | AF8: 0 | AG8: 0 | AH8: 6
A9: #URGR20J0 | B9: zeezus | C9: =_xlfn.XLOOKUP($A9,'01'!$G$3:$G$100,'01'!$R$3:$R$100,"-") | D9: =_xlfn.XLOOKUP($A9,'02'!$G$3:$G$100,'02'!$R$3:$R$100,"-") | E9: =_xlfn.XLOOKUP($A9,'03'!$G$3:$G$100,'03'!$R$3:$R$100,"-") | F9: =_xlfn.XLOOKUP($A9,'04'!$G$3:$G$100,'04'!$R$3:$R$100,"-") | G9: - | H9: =_xlfn.XLOOKUP($A9,'06'!$G$3:$G$100,'06'!$R$3:$R$100,"-") | I9: =_xlfn.XLOOKUP($A9,'07'!$G$3:$G$100,'07'!$R$3:$R$100,"-") | J9: =_xlfn.XLOOKUP($A9,'08'!$G$3:$G$100,'08'!$R$3:$R$100,"-") | K9: =_xlfn.XLOOKUP($A9,'09'!$G$3:$G$100,'09'!$R$3:$R$100,"-") | L9: =_xlfn.XLOOKUP($A9,'10'!$G$3:$G$100,'10'!$R$3:$R$100,"-") | M9: =_xlfn.XLOOKUP($A9,'11'!$G$3:$G$100,'11'!$R$3:$R$100,"-") | N9: =_xlfn.XLOOKUP($A9,'12'!$G$3:$G$100,'12'!$R$3:$R$100,"-") | O9: =SUM(C9:N9) | Q9: 7 | S9: zeezus | T9: - | U9: - | V9: - | W9: - | X9: - | Y9: - | Z9: - | AA9: - | AB9: - | AC9: - | AD9: - | AE9: - | AF9: 0 | AG9: 0 | AH9: 7
A10: #29G0L9JL9 | B10: Jesús F7 | C10: =_xlfn.XLOOKUP($A10,'01'!$G$3:$G$100,'01'!$R$3:$R$100,"-") | D10: =_xlfn.XLOOKUP($A10,'02'!$G$3:$G$100,'02'!$R$3:$R$100,"-") | E10: =_xlfn.XLOOKUP($A10,'03'!$G$3:$G$100,'03'!$R$3:$R$100,"-") | F10: =_xlfn.XLOOKUP($A10,'04'!$G$3:$G$100,'04'!$R$3:$R$100,"-") | G10: - | H10: =_xlfn.XLOOKUP($A10,'06'!$G$3:$G$100,'06'!$R$3:$R$100,"-") | I10: =_xlfn.XLOOKUP($A10,'07'!$G$3:$G$100,'07'!$R$3:$R$100,"-") | J10: =_xlfn.XLOOKUP($A10,'08'!$G$3:$G$100,'08'!$R$3:$R$100,"-") | K10: =_xlfn.XLOOKUP($A10,'09'!$G$3:$G$100,'09'!$R$3:$R$100,"-") | L10: =_xlfn.XLOOKUP($A10,'10'!$G$3:$G$100,'10'!$R$3:$R$100,"-") | M10: =_xlfn.XLOOKUP($A10,'11'!$G$3:$G$100,'11'!$R$3:$R$100,"-") | N10: =_xlfn.XLOOKUP($A10,'12'!$G$3:$G$100,'12'!$R$3:$R$100,"-") | O10: =SUM(C10:N10) | Q10: 8 | S10: Jesús F7 | T10: - | U10: - | V10: - | W10: - | X10: - | Y10: - | Z10: - | AA10: - | AB10: - | AC10: - | AD10: - | AE10: - | AF10: 0 | AG10: 0 | AH10: 8
A11: #JJ8Y9JU8 | B11: champagnebucci | C11: =_xlfn.XLOOKUP($A11,'01'!$G$3:$G$100,'01'!$R$3:$R$100,"-") | D11: =_xlfn.XLOOKUP($A11,'02'!$G$3:$G$100,'02'!$R$3:$R$100,"-") | E11: =_xlfn.XLOOKUP($A11,'03'!$G$3:$G$100,'03'!$R$3:$R$100,"-") | F11: =_xlfn.XLOOKUP($A11,'04'!$G$3:$G$100,'04'!$R$3:$R$100,"-") | G11: - | H11: =_xlfn.XLOOKUP($A11,'06'!$G$3:$G$100,'06'!$R$3:$R$100,"-") | I11: =_xlfn.XLOOKUP($A11,'07'!$G$3:$G$100,'07'!$R$3:$R$100,"-") | J11: =_xlfn.XLOOKUP($A11,'08'!$G$3:$G$100,'08'!$R$3:$R$100,"-") | K11: =_xlfn.XLOOKUP($A11,'09'!$G$3:$G$100,'09'!$R$3:$R$100,"-") | L11: =_xlfn.XLOOKUP($A11,'10'!$G$3:$G$100,'10'!$R$3:$R$100,"-") | M11: =_xlfn.XLOOKUP($A11,'11'!$G$3:$G$100,'11'!$R$3:$R$100,"-") | N11: =_xlfn.XLOOKUP($A11,'12'!$G$3:$G$100,'12'!$R$3:$R$100,"-") | O11: =SUM(C11:N11) | Q11: 9 | S11: champagnebucci | T11: - | U11: - | V11: - | W11: - | X11: - | Y11: - | Z11: - | AA11: - | AB11: - | AC11: - | AD11: - | AE11: - | AF11: 0 | AG11: 0 | AH11: 9
A12: #Y0RVYJVC | B12: ⚡️⚡️ G U S ⚡️⚡️ | C12: =_xlfn.XLOOKUP($A12,'01'!$G$3:$G$100,'01'!$R$3:$R$100,"-") | D12: =_xlfn.XLOOKUP($A12,'02'!$G$3:$G$100,'02'!$R$3:$R$100,"-") | E12: =_xlfn.XLOOKUP($A12,'03'!$G$3:$G$100,'03'!$R$3:$R$100,"-") | F12: =_xlfn.XLOOKUP($A12,'04'!$G$3:$G$100,'04'!$R$3:$R$100,"-") | G12: - | H12: =_xlfn.XLOOKUP($A12,'06'!$G$3:$G$100,'06'!$R$3:$R$100,"-") | I12: =_xlfn.XLOOKUP($A12,'07'!$G$3:$G$100,'07'!$R$3:$R$100,"-") | J12: =_xlfn.XLOOKUP($A12,'08'!$G$3:$G$100,'08'!$R$3:$R$100,"-") | K12: =_xlfn.XLOOKUP($A12,'09'!$G$3:$G$100,'09'!$R$3:$R$100,"-") | L12: =_xlfn.XLOOKUP($A12,'10'!$G$3:$G$100,'10'!$R$3:$R$100,"-") | M12: =_xlfn.XLOOKUP($A12,'11'!$G$3:$G$100,'11'!$R$3:$R$100,"-") | N12: =_xlfn.XLOOKUP($A12,'12'!$G$3:$G$100,'12'!$R$3:$R$100,"-") | O12: =SUM(C12:N12) | Q12: 10 | S12: ⚡️⚡️ G U S ⚡️⚡️ | T12: - | U12: - | V12: - | W12: - | X12: - | Y12: - | Z12: - | AA12: - | AB12: - | AC12: - | AD12: - | AE12: - | AF12: 0 | AG12: 0 | AH12: 10
A13: #YCVR9CC0C | B13: Bilbo_Swaggins | C13: =_xlfn.XLOOKUP($A13,'01'!$G$3:$G$100,'01'!$R$3:$R$100,"-") | D13: =_xlfn.XLOOKUP($A13,'02'!$G$3:$G$100,'02'!$R$3:$R$100,"-") | E13: =_xlfn.XLOOKUP($A13,'03'!$G$3:$G$100,'03'!$R$3:$R$100,"-") | F13: =_xlfn.XLOOKUP($A13,'04'!$G$3:$G$100,'04'!$R$3:$R$100,"-") | G13: - | H13: =_xlfn.XLOOKUP($A13,'06'!$G$3:$G$100,'06'!$R$3:$R$100,"-") | I13: =_xlfn.XLOOKUP($A13,'07'!$G$3:$G$100,'07'!$R$3:$R$100,"-") | J13: =_xlfn.XLOOKUP($A13,'08'!$G$3:$G$100,'08'!$R$3:$R$100,"-") | K13: =_xlfn.XLOOKUP($A13,'09'!$G$3:$G$100,'09'!$R$3:$R$100,"-") | L13: =_xlfn.XLOOKUP($A13,'10'!$G$3:$G$100,'10'!$R$3:$R$100,"-") | M13: =_xlfn.XLOOKUP($A13,'11'!$G$3:$G$100,'11'!$R$3:$R$100,"-") | N13: =_xlfn.XLOOKUP($A13,'12'!$G$3:$G$100,'12'!$R$3:$R$100,"-") | O13: =SUM(C13:N13) | Q13: 11 | S13: Bilbo_Swaggins | T13: - | U13: - | V13: - | W13: - | X13: - | Y13: - | Z13: - | AA13: - | AB13: - | AC13: - | AD13: - | AE13: - | AF13: 0 | AG13: 0 | AH13: 11
A14: #8JU98908G | B14: H@PP¥ | C14: =_xlfn.XLOOKUP($A14,'01'!$G$3:$G$100,'01'!$R$3:$R$100,"-") | D14: =_xlfn.XLOOKUP($A14,'02'!$G$3:$G$100,'02'!$R$3:$R$100,"-") | E14: =_xlfn.XLOOKUP($A14,'03'!$G$3:$G$100,'03'!$R$3:$R$100,"-") | F14: =_xlfn.XLOOKUP($A14,'04'!$G$3:$G$100,'04'!$R$3:$R$100,"-") | G14: - | H14: =_xlfn.XLOOKUP($A14,'06'!$G$3:$G$100,'06'!$R$3:$R$100,"-") | I14: =_xlfn.XLOOKUP($A14,'07'!$G$3:$G$100,'07'!$R$3:$R$100,"-") | J14: =_xlfn.XLOOKUP($A14,'08'!$G$3:$G$100,'08'!$R$3:$R$100,"-") | K14: =_xlfn.XLOOKUP($A14,'09'!$G$3:$G$100,'09'!$R$3:$R$100,"-") | L14: =_xlfn.XLOOKUP($A14,'10'!$G$3:$G$100,'10'!$R$3:$R$100,"-") | M14: =_xlfn.XLOOKUP($A14,'11'!$G$3:$G$100,'11'!$R$3:$R$100,"-") | N14: =_xlfn.XLOOKUP($A14,'12'!$G$3:$G$100,'12'!$R$3:$R$100,"-") | O14: =SUM(C14:N14) | Q14: 12 | S14: H@PP¥ | T14: - | U14: - | V14: - | W14: - | X14: - | Y14: - | Z14: - | AA14: - | AB14: - | AC14: - | AD14: - | AE14: - | AF14: 0 | AG14: 0 | AH14: 12
A15: #P920JLC0P | B15: EE Sp∆ce | C15: =_xlfn.XLOOKUP($A15,'01'!$G$3:$G$100,'01'!$R$3:$R$100,"-") | D15: =_xlfn.XLOOKUP($A15,'02'!$G$3:$G$100,'02'!$R$3:$R$100,"-") | E15: =_xlfn.XLOOKUP($A15,'03'!$G$3:$G$100,'03'!$R$3:$R$100,"-") | F15: =_xlfn.XLOOKUP($A15,'04'!$G$3:$G$100,'04'!$R$3:$R$100,"-") | G15: - | H15: =_xlfn.XLOOKUP($A15,'06'!$G$3:$G$100,'06'!$R$3:$R$100,"-") | I15: =_xlfn.XLOOKUP($A15,'07'!$G$3:$G$100,'07'!$R$3:$R$100,"-") | J15: =_xlfn.XLOOKUP($A15,'08'!$G$3:$G$100,'08'!$R$3:$R$100,"-") | K15: =_xlfn.XLOOKUP($A15,'09'!$G$3:$G$100,'09'!$R$3:$R$100,"-") | L15: =_xlfn.XLOOKUP($A15,'10'!$G$3:$G$100,'10'!$R$3:$R$100,"-") | M15: =_xlfn.XLOOKUP($A15,'11'!$G$3:$G$100,'11'!$R$3:$R$100,"-") | N15: =_xlfn.XLOOKUP($A15,'12'!$G$3:$G$100,'12'!$R$3:$R$100,"-") | O15: =SUM(C15:N15) | Q15: 13 | S15: EE Sp∆ce | T15: - | U15: - | V15: - | W15: - | X15: - | Y15: - | Z15: - | AA15: - | AB15: - | AC15: - | AD15: - | AE15: - | AF15: 0 | AG15: 0 | AH15: 13
A16: #C9UU0C9G | B16: Ace Fletch | C16: =_xlfn.XLOOKUP($A16,'01'!$G$3:$G$100,'01'!$R$3:$R$100,"-") | D16: =_xlfn.XLOOKUP($A16,'02'!$G$3:$G$100,'02'!$R$3:$R$100,"-") | E16: =_xlfn.XLOOKUP($A16,'03'!$G$3:$G$100,'03'!$R$3:$R$100,"-") | F16: =_xlfn.XLOOKUP($A16,'04'!$G$3:$G$100,'04'!$R$3:$R$100,"-") | G16: - | H16: =_xlfn.XLOOKUP($A16,'06'!$G$3:$G$100,'06'!$R$3:$R$100,"-") | I16: =_xlfn.XLOOKUP($A16,'07'!$G$3:$G$100,'07'!$R$3:$R$100,"-") | J16: =_xlfn.XLOOKUP($A16,'08'!$G$3:$G$100,'08'!$R$3:$R$100,"-") | K16: =_xlfn.XLOOKUP($A16,'09'!$G$3:$G$100,'09'!$R$3:$R$100,"-") | L16: =_xlfn.XLOOKUP($A16,'10'!$G$3:$G$100,'10'!$R$3:$R$100,"-") | M16: =_xlfn.XLOOKUP($A16,'11'!$G$3:$G$100,'11'!$R$3:$R$100,"-") | N16: =_xlfn.XLOOKUP($A16,'12'!$G$3:$G$100,'12'!$R$3:$R$100,"-") | O16: =SUM(C16:N16) | Q16: 14 | S16: Ace Fletch | T16: - | U16: - | V16: - | W16: - | X16: - | Y16: - | Z16: - | AA16: - | AB16: - | AC16: - | AD16: - | AE16: - | AF16: 0 | AG16: 0 | AH16: 14
A17: #9RCCUY28U | B17: Roman Rittik | C17: =_xlfn.XLOOKUP($A17,'01'!$G$3:$G$100,'01'!$R$3:$R$100,"-") | D17: =_xlfn.XLOOKUP($A17,'02'!$G$3:$G$100,'02'!$R$3:$R$100,"-") | E17: =_xlfn.XLOOKUP($A17,'03'!$G$3:$G$100,'03'!$R$3:$R$100,"-") | F17: =_xlfn.XLOOKUP($A17,'04'!$G$3:$G$100,'04'!$R$3:$R$100,"-") | G17: - | H17: =_xlfn.XLOOKUP($A17,'06'!$G$3:$G$100,'06'!$R$3:$R$100,"-") | I17: =_xlfn.XLOOKUP($A17,'07'!$G$3:$G$100,'07'!$R$3:$R$100,"-") | J17: =_xlfn.XLOOKUP($A17,'08'!$G$3:$G$100,'08'!$R$3:$R$100,"-") | K17: =_xlfn.XLOOKUP($A17,'09'!$G$3:$G$100,'09'!$R$3:$R$100,"-") | L17: =_xlfn.XLOOKUP($A17,'10'!$G$3:$G$100,'10'!$R$3:$R$100,"-") | M17: =_xlfn.XLOOKUP($A17,'11'!$G$3:$G$100,'11'!$R$3:$R$100,"-") | N17: =_xlfn.XLOOKUP($A17,'12'!$G$3:$G$100,'12'!$R$3:$R$100,"-") | O17: =SUM(C17:N17) | Q17: 15 | S17: Roman Rittik | T17: - | U17: - | V17: - | W17: - | X17: - | Y17: - | Z17: - | AA17: - | AB17: - | AC17: - | AD17: - | AE17: - | AF17: 0 | AG17: 0 | AH17: 15
C18: =_xlfn.XLOOKUP($A18,'01'!$G$3:$G$100,'01'!$R$3:$R$100,"-") | D18: =_xlfn.XLOOKUP($A18,'02'!$G$3:$G$100,'02'!$R$3:$R$100,"-") | E18: =_xlfn.XLOOKUP($A18,'03'!$G$3:$G$100,'03'!$R$3:$R$100,"-") | F18: =_xlfn.XLOOKUP($A18,'04'!$G$3:$G$100,'04'!$R$3:$R$100,"-") | G18: =_xlfn.XLOOKUP($A18,'05'!$G$3:$G$100,'05'!$R$3:$R$100,"-") | H18: =_xlfn.XLOOKUP($A18,'06'!$G$3:$G$100,'06'!$R$3:$R$100,"-") | I18: =_xlfn.XLOOKUP($A18,'07'!$G$3:$G$100,'07'!$R$3:$R$100,"-") | J18: =_xlfn.XLOOKUP($A18,'08'!$G$3:$G$100,'08'!$R$3:$R$100,"-") | K18: =_xlfn.XLOOKUP($A18,'09'!$G$3:$G$100,'09'!$R$3:$R$100,"-") | L18: =_xlfn.XLOOKUP($A18,'10'!$G$3:$G$100,'10'!$R$3:$R$100,"-") | M18: =_xlfn.XLOOKUP($A18,'11'!$G$3:$G$100,'11'!$R$3:$R$100,"-") | N18: =_xlfn.XLOOKUP($A18,'12'!$G$3:$G$100,'12'!$R$3:$R$100,"-") | O18: =SUM(C18:N18) | Q18: 16 | S18: 0 | T18: 0 | U18: 0 | V18: 0 | W18: 0 | X18: 0 | Y18: 0 | Z18: 0 | AA18: 0 | AB18: 0 | AC18: 0 | AD18: 0 | AE18: 0 | AF18: 0 | AG18: 0 | AH18: 16
C19: =_xlfn.XLOOKUP($A19,'01'!$G$3:$G$100,'01'!$R$3:$R$100,"-") | D19: =_xlfn.XLOOKUP($A19,'02'!$G$3:$G$100,'02'!$R$3:$R$100,"-") | E19: =_xlfn.XLOOKUP($A19,'03'!$G$3:$G$100,'03'!$R$3:$R$100,"-") | F19: =_xlfn.XLOOKUP($A19,'04'!$G$3:$G$100,'04'!$R$3:$R$100,"-") | G19: =_xlfn.XLOOKUP($A19,'05'!$G$3:$G$100,'05'!$R$3:$R$100,"-") | H19: =_xlfn.XLOOKUP($A19,'06'!$G$3:$G$100,'06'!$R$3:$R$100,"-") | I19: =_xlfn.XLOOKUP($A19,'07'!$G$3:$G$100,'07'!$R$3:$R$100,"-") | J19: =_xlfn.XLOOKUP($A19,'08'!$G$3:$G$100,'08'!$R$3:$R$100,"-") | K19: =_xlfn.XLOOKUP($A19,'09'!$G$3:$G$100,'09'!$R$3:$R$100,"-") | L19: =_xlfn.XLOOKUP($A19,'10'!$G$3:$G$100,'10'!$R$3:$R$100,"-") | M19: =_xlfn.XLOOKUP($A19,'11'!$G$3:$G$100,'11'!$R$3:$R$100,"-") | N19: =_xlfn.XLOOKUP($A19,'12'!$G$3:$G$100,'12'!$R$3:$R$100,"-") | O19: =SUM(C19:N19) | Q19: 17 | S19: 0 | T19: 0 | U19: 0 | V19: 0 | W19: 0 | X19: 0 | Y19: 0 | Z19: 0 | AA19: 0 | AB19: 0 | AC19: 0 | AD19: 0 | AE19: 0 | AF19: 0 | AG19: 0 | AH19: 17
C20: =_xlfn.XLOOKUP($A20,'01'!$G$3:$G$100,'01'!$R$3:$R$100,"-") | D20: =_xlfn.XLOOKUP($A20,'02'!$G$3:$G$100,'02'!$R$3:$R$100,"-") | E20: =_xlfn.XLOOKUP($A20,'03'!$G$3:$G$100,'03'!$R$3:$R$100,"-") | F20: =_xlfn.XLOOKUP($A20,'04'!$G$3:$G$100,'04'!$R$3:$R$100,"-") | G20: =_xlfn.XLOOKUP($A20,'05'!$G$3:$G$100,'05'!$R$3:$R$100,"-") | H20: =_xlfn.XLOOKUP($A20,'06'!$G$3:$G$100,'06'!$R$3:$R$100,"-") | I20: =_xlfn.XLOOKUP($A20,'07'!$G$3:$G$100,'07'!$R$3:$R$100,"-") | J20: =_xlfn.XLOOKUP($A20,'08'!$G$3:$G$100,'08'!$R$3:$R$100,"-") | K20: =_xlfn.XLOOKUP($A20,'09'!$G$3:$G$100,'09'!$R$3:$R$100,"-") | L20: =_xlfn.XLOOKUP($A20,'10'!$G$3:$G$100,'10'!$R$3:$R$100,"-") | M20: =_xlfn.XLOOKUP($A20,'11'!$G$3:$G$100,'11'!$R$3:$R$100,"-") | N20: =_xlfn.XLOOKUP($A20,'12'!$G$3:$G$100,'12'!$R$3:$R$100,"-") | O20: =SUM(C20:N20) | Q20: 18 | S20: 0 | T20: 0 | U20: 0 | V20: 0 | W20: 0 | X20: 0 | Y20: 0 | Z20: 0 | AA20: 0 | AB20: 0 | AC20: 0 | AD20: 0 | AE20: 0 | AF20: 0 | AG20: 0 | AH20: 18
C21: =_xlfn.XLOOKUP($A21,'01'!$G$3:$G$100,'01'!$R$3:$R$100,"-") | D21: =_xlfn.XLOOKUP($A21,'02'!$G$3:$G$100,'02'!$R$3:$R$100,"-") | E21: =_xlfn.XLOOKUP($A21,'03'!$G$3:$G$100,'03'!$R$3:$R$100,"-") | F21: =_xlfn.XLOOKUP($A21,'04'!$G$3:$G$100,'04'!$R$3:$R$100,"-") | G21: =_xlfn.XLOOKUP($A21,'05'!$G$3:$G$100,'05'!$R$3:$R$100,"-") | H21: =_xlfn.XLOOKUP($A21,'06'!$G$3:$G$100,'06'!$R$3:$R$100,"-") | I21: =_xlfn.XLOOKUP($A21,'07'!$G$3:$G$100,'07'!$R$3:$R$100,"-") | J21: =_xlfn.XLOOKUP($A21,'08'!$G$3:$G$100,'08'!$R$3:$R$100,"-") | K21: =_xlfn.XLOOKUP($A21,'09'!$G$3:$G$100,'09'!$R$3:$R$100,"-") | L21: =_xlfn.XLOOKUP($A21,'10'!$G$3:$G$100,'10'!$R$3:$R$100,"-") | M21: =_xlfn.XLOOKUP($A21,'11'!$G$3:$G$100,'11'!$R$3:$R$100,"-") | N21: =_xlfn.XLOOKUP($A21,'12'!$G$3:$G$100,'12'!$R$3:$R$100,"-") | O21: =SUM(C21:N21) | Q21: 19 | S21: 0 | T21: 0 | U21: 0 | V21: 0 | W21: 0 | X21: 0 | Y21: 0 | Z21: 0 | AA21: 0 | AB21: 0 | AC21: 0 | AD21: 0 | AE21: 0 | AF21: 0 | AG21: 0 | AH21: 19
C22: =_xlfn.XLOOKUP($A22,'01'!$G$3:$G$100,'01'!$R$3:$R$100,"-") | D22: =_xlfn.XLOOKUP($A22,'02'!$G$3:$G$100,'02'!$R$3:$R$100,"-") | E22: =_xlfn.XLOOKUP($A22,'03'!$G$3:$G$100,'03'!$R$3:$R$100,"-") | F22: =_xlfn.XLOOKUP($A22,'04'!$G$3:$G$100,'04'!$R$3:$R$100,"-") | G22: =_xlfn.XLOOKUP($A22,'05'!$G$3:$G$100,'05'!$R$3:$R$100,"-") | H22: =_xlfn.XLOOKUP($A22,'06'!$G$3:$G$100,'06'!$R$3:$R$100,"-") | I22: =_xlfn.XLOOKUP($A22,'07'!$G$3:$G$100,'07'!$R$3:$R$100,"-") | J22: =_xlfn.XLOOKUP($A22,'08'!$G$3:$G$100,'08'!$R$3:$R$100,"-") | K22: =_xlfn.XLOOKUP($A22,'09'!$G$3:$G$100,'09'!$R$3:$R$100,"-") | L22: =_xlfn.XLOOKUP($A22,'10'!$G$3:$G$100,'10'!$R$3:$R$100,"-") | M22: =_xlfn.XLOOKUP($A22,'11'!$G$3:$G$100,'11'!$R$3:$R$100,"-") | N22: =_xlfn.XLOOKUP($A22,'12'!$G$3:$G$100,'12'!$R$3:$R$100,"-") | O22: =SUM(C22:N22) | Q22: 20 | S22: 0 | T22: 0 | U22: 0 | V22: 0 | W22: 0 | X22: 0 | Y22: 0 | Z22: 0 | AA22: 0 | AB22: 0 | AC22: 0 | AD22: 0 | AE22: 0 | AF22: 0 | AG22: 0 | AH22: 20
C23: =_xlfn.XLOOKUP($A23,'01'!$G$3:$G$100,'01'!$R$3:$R$100,"-") | D23: =_xlfn.XLOOKUP($A23,'02'!$G$3:$G$100,'02'!$R$3:$R$100,"-") | E23: =_xlfn.XLOOKUP($A23,'03'!$G$3:$G$100,'03'!$R$3:$R$100,"-") | F23: =_xlfn.XLOOKUP($A23,'04'!$G$3:$G$100,'04'!$R$3:$R$100,"-") | G23: =_xlfn.XLOOKUP($A23,'05'!$G$3:$G$100,'05'!$R$3:$R$100,"-") | H23: =_xlfn.XLOOKUP($A23,'06'!$G$3:$G$100,'06'!$R$3:$R$100,"-") | I23: =_xlfn.XLOOKUP($A23,'07'!$G$3:$G$100,'07'!$R$3:$R$100,"-") | J23: =_xlfn.XLOOKUP($A23,'08'!$G$3:$G$100,'08'!$R$3:$R$100,"-") | K23: =_xlfn.XLOOKUP($A23,'09'!$G$3:$G$100,'09'!$R$3:$R$100,"-") | L23: =_xlfn.XLOOKUP($A23,'10'!$G$3:$G$100,'10'!$R$3:$R$100,"-") | M23: =_xlfn.XLOOKUP($A23,'11'!$G$3:$G$100,'11'!$R$3:$R$100,"-") | N23: =_xlfn.XLOOKUP($A23,'12'!$G$3:$G$100,'12'!$R$3:$R$100,"-") | O23: =SUM(C23:N23) | Q23: 21 | S23: 0 | T23: 0 | U23: 0 | V23: 0 | W23: 0 | X23: 0 | Y23: 0 | Z23: 0 | AA23: 0 | AB23: 0 | AC23: 0 | AD23: 0 | AE23: 0 | AF23: 0 | AG23: 0 | AH23: 21
C24: =_xlfn.XLOOKUP($A24,'01'!$G$3:$G$100,'01'!$R$3:$R$100,"-") | D24: =_xlfn.XLOOKUP($A24,'02'!$G$3:$G$100,'02'!$R$3:$R$100,"-") | E24: =_xlfn.XLOOKUP($A24,'03'!$G$3:$G$100,'03'!$R$3:$R$100,"-") | F24: =_xlfn.XLOOKUP($A24,'04'!$G$3:$G$100,'04'!$R$3:$R$100,"-") | G24: =_xlfn.XLOOKUP($A24,'05'!$G$3:$G$100,'05'!$R$3:$R$100,"-") | H24: =_xlfn.XLOOKUP($A24,'06'!$G$3:$G$100,'06'!$R$3:$R$100,"-") | I24: =_xlfn.XLOOKUP($A24,'07'!$G$3:$G$100,'07'!$R$3:$R$100,"-") | J24: =_xlfn.XLOOKUP($A24,'08'!$G$3:$G$100,'08'!$R$3:$R$100,"-") | K24: =_xlfn.XLOOKUP($A24,'09'!$G$3:$G$100,'09'!$R$3:$R$100,"-") | L24: =_xlfn.XLOOKUP($A24,'10'!$G$3:$G$100,'10'!$R$3:$R$100,"-") | M24: =_xlfn.XLOOKUP($A24,'11'!$G$3:$G$100,'11'!$R$3:$R$100,"-") | N24: =_xlfn.XLOOKUP($A24,'12'!$G$3:$G$100,'12'!$R$3:$R$100,"-") | O24: =SUM(C24:N24) | Q24: 22 | S24: 0 | T24: 0 | U24: 0 | V24: 0 | W24: 0 | X24: 0 | Y24: 0 | Z24: 0 | AA24: 0 | AB24: 0 | AC24: 0 | AD24: 0 | AE24: 0 | AF24: 0 | AG24: 0 | AH24: 22
C25: =_xlfn.XLOOKUP($A25,'01'!$G$3:$G$100,'01'!$R$3:$R$100,"-") | D25: =_xlfn.XLOOKUP($A25,'02'!$G$3:$G$100,'02'!$R$3:$R$100,"-") | E25: =_xlfn.XLOOKUP($A25,'03'!$G$3:$G$100,'03'!$R$3:$R$100,"-") | F25: =_xlfn.XLOOKUP($A25,'04'!$G$3:$G$100,'04'!$R$3:$R$100,"-") | G25: =_xlfn.XLOOKUP($A25,'05'!$G$3:$G$100,'05'!$R$3:$R$100,"-") | H25: =_xlfn.XLOOKUP($A25,'06'!$G$3:$G$100,'06'!$R$3:$R$100,"-") | I25: =_xlfn.XLOOKUP($A25,'07'!$G$3:$G$100,'07'!$R$3:$R$100,"-") | J25: =_xlfn.XLOOKUP($A25,'08'!$G$3:$G$100,'08'!$R$3:$R$100,"-") | K25: =_xlfn.XLOOKUP($A25,'09'!$G$3:$G$100,'09'!$R$3:$R$100,"-") | L25: =_xlfn.XLOOKUP($A25,'10'!$G$3:$G$100,'10'!$R$3:$R$100,"-") | M25: =_xlfn.XLOOKUP($A25,'11'!$G$3:$G$100,'11'!$R$3:$R$100,"-") | N25: =_xlfn.XLOOKUP($A25,'12'!$G$3:$G$100,'12'!$R$3:$R$100,"-") | O25: =SUM(C25:N25) | Q25: 23 | S25: 0 | T25: 0 | U25: 0 | V25: 0 | W25: 0 | X25: 0 | Y25: 0 | Z25: 0 | AA25: 0 | AB25: 0 | AC25: 0 | AD25: 0 | AE25: 0 | AF25: 0 | AG25: 0 | AH25: 23
C26: =_xlfn.XLOOKUP($A26,'01'!$G$3:$G$100,'01'!$R$3:$R$100,"-") | D26: =_xlfn.XLOOKUP($A26,'02'!$G$3:$G$100,'02'!$R$3:$R$100,"-") | E26: =_xlfn.XLOOKUP($A26,'03'!$G$3:$G$100,'03'!$R$3:$R$100,"-") | F26: =_xlfn.XLOOKUP($A26,'04'!$G$3:$G$100,'04'!$R$3:$R$100,"-") | G26: =_xlfn.XLOOKUP($A26,'05'!$G$3:$G$100,'05'!$R$3:$R$100,"-") | H26: =_xlfn.XLOOKUP($A26,'06'!$G$3:$G$100,'06'!$R$3:$R$100,"-") | I26: =_xlfn.XLOOKUP($A26,'07'!$G$3:$G$100,'07'!$R$3:$R$100,"-") | J26: =_xlfn.XLOOKUP($A26,'08'!$G$3:$G$100,'08'!$R$3:$R$100,"-") | K26: =_xlfn.XLOOKUP($A26,'09'!$G$3:$G$100,'09'!$R$3:$R$100,"-") | L26: =_xlfn.XLOOKUP($A26,'10'!$G$3:$G$100,'10'!$R$3:$R$100,"-") | M26: =_xlfn.XLOOKUP($A26,'11'!$G$3:$G$100,'11'!$R$3:$R$100,"-") | N26: =_xlfn.XLOOKUP($A26,'12'!$G$3:$G$100,'12'!$R$3:$R$100,"-") | O26: =SUM(C26:N26) | Q26: 24 | S26: 0 | T26: 0 | U26: 0 | V26: 0 | W26: 0 | X26: 0 | Y26: 0 | Z26: 0 | AA26: 0 | AB26: 0 | AC26: 0 | AD26: 0 | AE26: 0 | AF26: 0 | AG26: 0 | AH26: 24
C27: =_xlfn.XLOOKUP($A27,'01'!$G$3:$G$100,'01'!$R$3:$R$100,"-") | D27: =_xlfn.XLOOKUP($A27,'02'!$G$3:$G$100,'02'!$R$3:$R$100,"-") | E27: =_xlfn.XLOOKUP($A27,'03'!$G$3:$G$100,'03'!$R$3:$R$100,"-") | F27: =_xlfn.XLOOKUP($A27,'04'!$G$3:$G$100,'04'!$R$3:$R$100,"-") | G27: =_xlfn.XLOOKUP($A27,'05'!$G$3:$G$100,'05'!$R$3:$R$100,"-") | H27: =_xlfn.XLOOKUP($A27,'06'!$G$3:$G$100,'06'!$R$3:$R$100,"-") | I27: =_xlfn.XLOOKUP($A27,'07'!$G$3:$G$100,'07'!$R$3:$R$100,"-") | J27: =_xlfn.XLOOKUP($A27,'08'!$G$3:$G$100,'08'!$R$3:$R$100,"-") | K27: =_xlfn.XLOOKUP($A27,'09'!$G$3:$G$100,'09'!$R$3:$R$100,"-") | L27: =_xlfn.XLOOKUP($A27,'10'!$G$3:$G$100,'10'!$R$3:$R$100,"-") | M27: =_xlfn.XLOOKUP($A27,'11'!$G$3:$G$100,'11'!$R$3:$R$100,"-") | N27: =_xlfn.XLOOKUP($A27,'12'!$G$3:$G$100,'12'!$R$3:$R$100,"-") | O27: =SUM(C27:N27) | Q27: 25 | S27: 0 | T27: 0 | U27: 0 | V27: 0 | W27: 0 | X27: 0 | Y27: 0 | Z27: 0 | AA27: 0 | AB27: 0 | AC27: 0 | AD27: 0 | AE27: 0 | AF27: 0 | AG27: 0 | AH27: 25
C28: =_xlfn.XLOOKUP($A28,'01'!$G$3:$G$100,'01'!$R$3:$R$100,"-") | D28: =_xlfn.XLOOKUP($A28,'02'!$G$3:$G$100,'02'!$R$3:$R$100,"-") | E28: =_xlfn.XLOOKUP($A28,'03'!$G$3:$G$100,'03'!$R$3:$R$100,"-") | F28: =_xlfn.XLOOKUP($A28,'04'!$G$3:$G$100,'04'!$R$3:$R$100,"-") | G28: =_xlfn.XLOOKUP($A28,'05'!$G$3:$G$100,'05'!$R$3:$R$100,"-") | H28: =_xlfn.XLOOKUP($A28,'06'!$G$3:$G$100,'06'!$R$3:$R$100,"-") | I28: =_xlfn.XLOOKUP($A28,'07'!$G$3:$G$100,'07'!$R$3:$R$100,"-") | J28: =_xlfn.XLOOKUP($A28,'08'!$G$3:$G$100,'08'!$R$3:$R$100,"-") | K28: =_xlfn.XLOOKUP($A28,'09'!$G$3:$G$100,'09'!$R$3:$R$100,"-") | L28: =_xlfn.XLOOKUP($A28,'10'!$G$3:$G$100,'10'!$R$3:$R$100,"-") | M28: =_xlfn.XLOOKUP($A28,'11'!$G$3:$G$100,'11'!$R$3:$R$100,"-") | N28: =_xlfn.XLOOKUP($A28,'12'!$G$3:$G$100,'12'!$R$3:$R$100,"-") | O28: =SUM(C28:N28) | Q28: 26 | S28: 0 | T28: 0 | U28: 0 | V28: 0 | W28: 0 | X28: 0 | Y28: 0 | Z28: 0 | AA28: 0 | AB28: 0 | AC28: 0 | AD28: 0 | AE28: 0 | AF28: 0 | AG28: 0 | AH28: 26
C29: =_xlfn.XLOOKUP($A29,'01'!$G$3:$G$100,'01'!$R$3:$R$100,"-") | D29: =_xlfn.XLOOKUP($A29,'02'!$G$3:$G$100,'02'!$R$3:$R$100,"-") | E29: =_xlfn.XLOOKUP($A29,'03'!$G$3:$G$100,'03'!$R$3:$R$100,"-") | F29: =_xlfn.XLOOKUP($A29,'04'!$G$3:$G$100,'04'!$R$3:$R$100,"-") | G29: =_xlfn.XLOOKUP($A29,'05'!$G$3:$G$100,'05'!$R$3:$R$100,"-") | H29: =_xlfn.XLOOKUP($A29,'06'!$G$3:$G$100,'06'!$R$3:$R$100,"-") | I29: =_xlfn.XLOOKUP($A29,'07'!$G$3:$G$100,'07'!$R$3:$R$100,"-") | J29: =_xlfn.XLOOKUP($A29,'08'!$G$3:$G$100,'08'!$R$3:$R$100,"-") | K29: =_xlfn.XLOOKUP($A29,'09'!$G$3:$G$100,'09'!$R$3:$R$100,"-") | L29: =_xlfn.XLOOKUP($A29,'10'!$G$3:$G$100,'10'!$R$3:$R$100,"-") | M29: =_xlfn.XLOOKUP($A29,'11'!$G$3:$G$100,'11'!$R$3:$R$100,"-") | N29: =_xlfn.XLOOKUP($A29,'12'!$G$3:$G$100,'12'!$R$3:$R$100,"-") | O29: =SUM(C29:N29) | Q29: 27 | S29: 0 | T29: 0 | U29: 0 | V29: 0 | W29: 0 | X29: 0 | Y29: 0 | Z29: 0 | AA29: 0 | AB29: 0 | AC29: 0 | AD29: 0 | AE29: 0 | AF29: 0 | AG29: 0 | AH29: 27
... C500: =_xlfn.XLOOKUP($A500,'01'!$G$3:$G$100,'01'!$R$3:$R$100,"-") | D500: =_xlfn.XLOOKUP($A500,'02'!$G$3:$G$100,'02'!$R$3:$R$100,"-") | E500: =_xlfn.XLOOKUP($A500,'03'!$G$3:$G$100,'03'!$R$3:$R$100,"-") | F500: =_xlfn.XLOOKUP($A500,'04'!$G$3:$G$100,'04'!$R$3:$R$100,"-") | G500: =_xlfn.XLOOKUP($A500,'05'!$G$3:$G$100,'05'!$R$3:$R$100,"-") | H500: =_xlfn.XLOOKUP($A500,'06'!$G$3:$G$100,'06'!$R$3:$R$100,"-") | I500: =_xlfn.XLOOKUP($A500,'07'!$G$3:$G$100,'07'!$R$3:$R$100,"-") | J500: =_xlfn.XLOOKUP($A500,'08'!$G$3:$G$100,'08'!$R$3:$R$100,"-") | K500: =_xlfn.XLOOKUP($A500,'09'!$G$3:$G$100,'09'!$R$3:$R$100,"-") | L500: =_xlfn.XLOOKUP($A500,'10'!$G$3:$G$100,'10'!$R$3:$R$100,"-") | M500: =_xlfn.XLOOKUP($A500,'11'!$G$3:$G$100,'11'!$R$3:$R$100,"-") | N500: =_xlfn.XLOOKUP($A500,'12'!$G$3:$G$100,'12'!$R$3:$R$100,"-") | O500: =SUM(C500:N500) | Q500: 498 | S500: 0 | T500: 0 | U500: 0 | V500: 0 | W500: 0 | X500: 0 | Y500: 0 | Z500: 0 | AA500: 0 | AB500: 0 | AC500: 0 | AD500: 0 | AE500: 0 | AF500: 0 | AG500: 0 | AH500: 498

Sheet 01
H1: War | I1: 1 | J1: 2 | K1: 3 | L1: 4 | M1: 5 | N1: 6 | O1: 7 | Q1: % max stars earned | R1: Total stars | S1: Triples | T1: Doubles | U1: Singles | V1: Fails | W1: Misses | X1: % Destruction | Y1: Opted out | AB1: War | AC1: 1 | AD1: 2 | AE1: 3 | AF1: 4 | AG1: 5 | AH1: 6 | AI1: 7 | AK1: % max stars earned | AL1: Total stars | AM1: 3 stars | AN1: 2 stars | AO1: 1 stars | AP1: 0 stars | AQ1: Misses | AR1: % Destruction | AS1: Opted out
H2: Players | AB2: Players
H3: =_xlfn.XLOOKUP(G3,A1:A104,D1:D104) | I3: =IFERROR(IF($E$3=15,IF(_xlfn.XLOOKUP(G3,A$3:A$17,B$3:B$17) = "Missed Hit",_xlfn.XLOOKUP(G3,A$3:A$17,B$3:B$17),_xlfn.XLOOKUP(G3,A$3:A$17,B$3:B$17) & " Star " & _xlfn.XLOOKUP(G3,A$3:A$17,C$3:C$17) & "%"),_xlfn.XLOOKUP(G3,A$3:A$32,B$3:B$32)),"Not in war") | J3: =IFERROR(IF($E$3=15,IF(_xlfn.XLOOKUP(G3,A$18:A$32,B$18:B$32) = "Missed Hit",_xlfn.XLOOKUP(G3,A$18:A$32,B$18:B$32),_xlfn.XLOOKUP(G3,A$18:A$32,B$18:B$32) & " Star " & _xlfn.XLOOKUP(G3,A$18:A$32,C$18:C$32) & "%"),_xlfn.XLOOKUP(G3,A$33:A$62,B$33:B$62)),"Not in war") | K3: =IFERROR(IF($E$3=15,IF(_xlfn.XLOOKUP(G3,A$33:A$47,B$33:B$47) = "Missed Hit",_xlfn.XLOOKUP(G3,A$33:A$47,B$33:B$47),_xlfn.XLOOKUP(G3,A$33:A$47,B$33:B$47) & " Star " & _xlfn.XLOOKUP(G3,A$33:A$47,C$33:C$47) & "%"),_xlfn.XLOOKUP(G3,A$63:A$92,B$63:B$92)),"Not in war") | L3: =IFERROR(IF($E$3=15,IF(_xlfn.XLOOKUP(G3,A$48:A$62,B$48:B$62) = "Missed Hit",_xlfn.XLOOKUP(G3,A$48:A$62,B$48:B$62),_xlfn.XLOOKUP(G3,A$48:A$62,B$48:B$62) & " Star " & _xlfn.XLOOKUP(G3,A$48:A$62,C$48:C$62) & "%"),_xlfn.XLOOKUP(G3,A$93:A$122,B$93:B$122)),"Not in war") | M3: =IFERROR(IF($E$3=15,IF(_xlfn.XLOOKUP(G3,A$63:A$77,B$63:B$77) = "Missed Hit",_xlfn.XLOOKUP(G3,A$63:A$77,B$63:B$77),_xlfn.XLOOKUP(G3,A$63:A$77,B$63:B$77) & " Star " & _xlfn.XLOOKUP(G3,A$63:A$77,C$63:C$77) & "%"),_xlfn.XLOOKUP(G3,A$123:A$152,B$123:B$152)),"Not in war") | N3: =IFERROR(IF($E$3=15,IF(_xlfn.XLOOKUP(G3,A$78:A$92,B$78:B$92) = "Missed Hit",_xlfn.XLOOKUP(G3,A$78:A$92,B$78:B$92),_xlfn.XLOOKUP(G3,A$78:A$92,B$78:B$92) & " Star " & _xlfn.XLOOKUP(G3,A$78:A$92,C$78:C$92) & "%"),_xlfn.XLOOKUP(G3,A$153:A$182,B$153:B$182)),"Not in war") | O3: =IFERROR(IF($E$3=15,IF(_xlfn.XLOOKUP(G3,A$93:A$107,B$93:B$107) = "Missed Hit",_xlfn.XLOOKUP(G3,A$93:A$107,B$93:B$107),_xlfn.XLOOKUP(G3,A$93:A$107,B$93:B$107) & " Star " & _xlfn.XLOOKUP(G3,A$93:A$107,C$93:C$107) & "%"),_xlfn.XLOOKUP(G3,A$153:A$182,B$153:B$182)),"Not in war") | Q3: =IFERROR($R3/(3*(7-$Y3)),0) | R3: =3*S3+2*T3+U3 | S3: =COUNTIF($I3:$O3, 3 & "*") | T3: =COUNTIF($I3:$O3, 2 & "*") | U3: =COUNTIF($I3:$O3, 1 & "*") | V3: =COUNTIF($I3:$O3, 0 & "*") | W3: =COUNTIF($I3:$O3,"Missed hit") | X3: =IF($E$3=15,SUM(_xlfn.XLOOKUP(G3,$A$3:$A$17,$C$3:$C$17,0),_xlfn.XLOOKUP(G3,$A$18:$A$32,$C$18:$C$32,0),_xlfn.XLOOKUP(G3,$A$33:$A$47,$C$33:$C$47,0), _xlfn.XLOOKUP(G3,$A$48:$A$62,$C$48:$C$62,0), _xlfn.XLOOKUP(G3,$A$63:$A$77,$C$63:$C$77,0), _xlfn.XLOOKUP(G3,$A$78:$A$92,$C$78:$C$92,0), _xlfn.XLOOKUP(G3,$A$93:$A$107,$C$93:$C$107,0))) | Y3: =COUNTIF($I3:$O3,"Not in war") | AB3: {=_xlfn.SORTBY(H3:Y100,$R$3:$R$100,-1,$X$3:$X$100,-1)} | AC3: 0 | AD3: 0 | AE3: 0 | AF3: 0 | AG3: 0 | AH3: 0 | AI3: 0 | AJ3: 0 | AK3: 0 | AL3: 0 | AM3: 0 | AN3: 0 | AO3: 0 | AP3: 0 | AQ3: 0 | AR3: FALSE | AS3: 0
H4: =_xlfn.XLOOKUP(G4,A2:A93,D2:D93) | I4: =IFERROR(IF($E$3=15,IF(_xlfn.XLOOKUP(G4,A$3:A$17,B$3:B$17) = "Missed Hit",_xlfn.XLOOKUP(G4,A$3:A$17,B$3:B$17),_xlfn.XLOOKUP(G4,A$3:A$17,B$3:B$17) & " Star " & _xlfn.XLOOKUP(G4,A$3:A$17,C$3:C$17) & "%"),_xlfn.XLOOKUP(G4,A$3:A$32,B$3:B$32)),"Not in war") | J4: =IFERROR(IF($E$3=15,IF(_xlfn.XLOOKUP(G4,A$18:A$32,B$18:B$32) = "Missed Hit",_xlfn.XLOOKUP(G4,A$18:A$32,B$18:B$32),_xlfn.XLOOKUP(G4,A$18:A$32,B$18:B$32) & " Star " & _xlfn.XLOOKUP(G4,A$18:A$32,C$18:C$32) & "%"),_xlfn.XLOOKUP(G4,A$33:A$62,B$33:B$62)),"Not in war") | K4: =IFERROR(IF($E$3=15,IF(_xlfn.XLOOKUP(G4,A$33:A$47,B$33:B$47) = "Missed Hit",_xlfn.XLOOKUP(G4,A$33:A$47,B$33:B$47),_xlfn.XLOOKUP(G4,A$33:A$47,B$33:B$47) & " Star " & _xlfn.XLOOKUP(G4,A$33:A$47,C$33:C$47) & "%"),_xlfn.XLOOKUP(G4,A$63:A$92,B$63:B$92)),"Not in war") | L4: =IFERROR(IF($E$3=15,IF(_xlfn.XLOOKUP(G4,A$48:A$62,B$48:B$62) = "Missed Hit",_xlfn.XLOOKUP(G4,A$48:A$62,B$48:B$62),_xlfn.XLOOKUP(G4,A$48:A$62,B$48:B$62) & " Star " & _xlfn.XLOOKUP(G4,A$48:A$62,C$48:C$62) & "%"),_xlfn.XLOOKUP(G4,A$93:A$122,B$93:B$122)),"Not in war") | M4: =IFERROR(IF($E$3=15,IF(_xlfn.XLOOKUP(G4,A$63:A$77,B$63:B$77) = "Missed Hit",_xlfn.XLOOKUP(G4,A$63:A$77,B$63:B$77),_xlfn.XLOOKUP(G4,A$63:A$77,B$63:B$77) & " Star " & _xlfn.XLOOKUP(G4,A$63:A$77,C$63:C$77) & "%"),_xlfn.XLOOKUP(G4,A$123:A$152,B$123:B$152)),"Not in war") | N4: =IFERROR(IF($E$3=15,IF(_xlfn.XLOOKUP(G4,A$78:A$92,B$78:B$92) = "Missed Hit",_xlfn.XLOOKUP(G4,A$78:A$92,B$78:B$92),_xlfn.XLOOKUP(G4,A$78:A$92,B$78:B$92) & " Star " & _xlfn.XLOOKUP(G4,A$78:A$92,C$78:C$92) & "%"),_xlfn.XLOOKUP(G4,A$153:A$182,B$153:B$182)),"Not in war") | O4: =IFERROR(IF($E$3=15,IF(_xlfn.XLOOKUP(G4,A$93:A$107,B$93:B$107) = "Missed Hit",_xlfn.XLOOKUP(G4,A$93:A$107,B$93:B$107),_xlfn.XLOOKUP(G4,A$93:A$107,B$93:B$107) & " Star " & _xlfn.XLOOKUP(G4,A$93:A$107,C$93:C$107) & "%"),_xlfn.XLOOKUP(G4,A$153:A$182,B$153:B$182)),"Not in war") | Q4: =IFERROR($R4/(3*(7-$Y4)),0) | R4: =3*S4+2*T4+U4 | S4: =COUNTIF($I4:$O4, 3 & "*") | T4: =COUNTIF($I4:$O4, 2 & "*") | U4: =COUNTIF($I4:$O4, 1 & "*") | V4: =COUNTIF($I4:$O4, 0 & "*") | W4: =COUNTIF($I4:$O4,"Missed hit") | X4: =IF($E$3=15,SUM(_xlfn.XLOOKUP(G4,$A$3:$A$17,$C$3:$C$17,0),_xlfn.XLOOKUP(G4,$A$18:$A$32,$C$18:$C$32,0),_xlfn.XLOOKUP(G4,$A$33:$A$47,$C$33:$C$47,0), _xlfn.XLOOKUP(G4,$A$48:$A$62,$C$48:$C$62,0), _xlfn.XLOOKUP(G4,$A$63:$A$77,$C$63:$C$77,0), _xlfn.XLOOKUP(G4,$A$78:$A$92,$C$78:$C$92,0), _xlfn.XLOOKUP(G4,$A$93:$A$107,$C$93:$C$107,0))) | Y4: =COUNTIF($I4:$O4,"Not in war") | AB4: 0 | AC4: 0 | AD4: 0 | AE4: 0 | AF4: 0 | AG4: 0 | AH4: 0 | AI4: 0 | AJ4: 0 | AK4: 0 | AL4: 0 | AM4: 0 | AN4: 0 | AO4: 0 | AP4: 0 | AQ4: 0 | AR4: FALSE | AS4: 0
H5: =_xlfn.XLOOKUP(G5,A2:A93,D2:D93) | I5: =IFERROR(IF($E$3=15,IF(_xlfn.XLOOKUP(G5,A$3:A$17,B$3:B$17) = "Missed Hit",_xlfn.XLOOKUP(G5,A$3:A$17,B$3:B$17),_xlfn.XLOOKUP(G5,A$3:A$17,B$3:B$17) & " Star " & _xlfn.XLOOKUP(G5,A$3:A$17,C$3:C$17) & "%"),_xlfn.XLOOKUP(G5,A$3:A$32,B$3:B$32)),"Not in war") | J5: =IFERROR(IF($E$3=15,IF(_xlfn.XLOOKUP(G5,A$18:A$32,B$18:B$32) = "Missed Hit",_xlfn.XLOOKUP(G5,A$18:A$32,B$18:B$32),_xlfn.XLOOKUP(G5,A$18:A$32,B$18:B$32) & " Star " & _xlfn.XLOOKUP(G5,A$18:A$32,C$18:C$32) & "%"),_xlfn.XLOOKUP(G5,A$33:A$62,B$33:B$62)),"Not in war") | K5: =IFERROR(IF($E$3=15,IF(_xlfn.XLOOKUP(G5,A$33:A$47,B$33:B$47) = "Missed Hit",_xlfn.XLOOKUP(G5,A$33:A$47,B$33:B$47),_xlfn.XLOOKUP(G5,A$33:A$47,B$33:B$47) & " Star " & _xlfn.XLOOKUP(G5,A$33:A$47,C$33:C$47) & "%"),_xlfn.XLOOKUP(G5,A$63:A$92,B$63:B$92)),"Not in war") | L5: =IFERROR(IF($E$3=15,IF(_xlfn.XLOOKUP(G5,A$48:A$62,B$48:B$62) = "Missed Hit",_xlfn.XLOOKUP(G5,A$48:A$62,B$48:B$62),_xlfn.XLOOKUP(G5,A$48:A$62,B$48:B$62) & " Star " & _xlfn.XLOOKUP(G5,A$48:A$62,C$48:C$62) & "%"),_xlfn.XLOOKUP(G5,A$93:A$122,B$93:B$122)),"Not in war") | M5: =IFERROR(IF($E$3=15,IF(_xlfn.XLOOKUP(G5,A$63:A$77,B$63:B$77) = "Missed Hit",_xlfn.XLOOKUP(G5,A$63:A$77,B$63:B$77),_xlfn.XLOOKUP(G5,A$63:A$77,B$63:B$77) & " Star " & _xlfn.XLOOKUP(G5,A$63:A$77,C$63:C$77) & "%"),_xlfn.XLOOKUP(G5,A$123:A$152,B$123:B$152)),"Not in war") | N5: =IFERROR(IF($E$3=15,IF(_xlfn.XLOOKUP(G5,A$78:A$92,B$78:B$92) = "Missed Hit",_xlfn.XLOOKUP(G5,A$78:A$92,B$78:B$92),_xlfn.XLOOKUP(G5,A$78:A$92,B$78:B$92) & " Star " & _xlfn.XLOOKUP(G5,A$78:A$92,C$78:C$92) & "%"),_xlfn.XLOOKUP(G5,A$153:A$182,B$153:B$182)),"Not in war") | O5: =IFERROR(IF($E$3=15,IF(_xlfn.XLOOKUP(G5,A$93:A$107,B$93:B$107) = "Missed Hit",_xlfn.XLOOKUP(G5,A$93:A$107,B$93:B$107),_xlfn.XLOOKUP(G5,A$93:A$107,B$93:B$107) & " Star " & _xlfn.XLOOKUP(G5,A$93:A$107,C$93:C$107) & "%"),_xlfn.XLOOKUP(G5,A$153:A$182,B$153:B$182)),"Not in war") | Q5: =IFERROR($R5/(3*(7-$Y5)),0) | R5: =3*S5+2*T5+U5 | S5: =COUNTIF($I5:$O5, 3 & "*") | T5: =COUNTIF($I5:$O5, 2 & "*") | U5: =COUNTIF($I5:$O5, 1 & "*") | V5: =COUNTIF($I5:$O5, 0 & "*") | W5: =COUNTIF($I5:$O5,"Missed hit") | X5: =IF($E$3=15,SUM(_xlfn.XLOOKUP(G5,$A$3:$A$17,$C$3:$C$17,0),_xlfn.XLOOKUP(G5,$A$18:$A$32,$C$18:$C$32,0),_xlfn.XLOOKUP(G5,$A$33:$A$47,$C$33:$C$47,0), _xlfn.XLOOKUP(G5,$A$48:$A$62,$C$48:$C$62,0), _xlfn.XLOOKUP(G5,$A$63:$A$77,$C$63:$C$77,0), _xlfn.XLOOKUP(G5,$A$78:$A$92,$C$78:$C$92,0), _xlfn.XLOOKUP(G5,$A$93:$A$107,$C$93:$C$107,0))) | Y5: =COUNTIF($I5:$O5,"Not in war") | AB5: 0 | AC5: 0 | AD5: 0 | AE5: 0 | AF5: 0 | AG5: 0 | AH5: 0 | AI5: 0 | AJ5: 0 | AK5: 0 | AL5: 0 | AM5: 0 | AN5: 0 | AO5: 0 | AP5: 0 | AQ5: 0 | AR5: FALSE | AS5: 0
H6: =_xlfn.XLOOKUP(G6,A1:A100,D1:D100) | I6: =IFERROR(IF($E$3=15,IF(_xlfn.XLOOKUP(G6,A$3:A$17,B$3:B$17) = "Missed Hit",_xlfn.XLOOKUP(G6,A$3:A$17,B$3:B$17),_xlfn.XLOOKUP(G6,A$3:A$17,B$3:B$17) & " Star " & _xlfn.XLOOKUP(G6,A$3:A$17,C$3:C$17) & "%"),_xlfn.XLOOKUP(G6,A$3:A$32,B$3:B$32)),"Not in war") | J6: =IFERROR(IF($E$3=15,IF(_xlfn.XLOOKUP(G6,A$18:A$32,B$18:B$32) = "Missed Hit",_xlfn.XLOOKUP(G6,A$18:A$32,B$18:B$32),_xlfn.XLOOKUP(G6,A$18:A$32,B$18:B$32) & " Star " & _xlfn.XLOOKUP(G6,A$18:A$32,C$18:C$32) & "%"),_xlfn.XLOOKUP(G6,A$33:A$62,B$33:B$62)),"Not in war") | K6: =IFERROR(IF($E$3=15,IF(_xlfn.XLOOKUP(G6,A$33:A$47,B$33:B$47) = "Missed Hit",_xlfn.XLOOKUP(G6,A$33:A$47,B$33:B$47),_xlfn.XLOOKUP(G6,A$33:A$47,B$33:B$47) & " Star " & _xlfn.XLOOKUP(G6,A$33:A$47,C$33:C$47) & "%"),_xlfn.XLOOKUP(G6,A$63:A$92,B$63:B$92)),"Not in war") | L6: =IFERROR(IF($E$3=15,IF(_xlfn.XLOOKUP(G6,A$48:A$62,B$48:B$62) = "Missed Hit",_xlfn.XLOOKUP(G6,A$48:A$62,B$48:B$62),_xlfn.XLOOKUP(G6,A$48:A$62,B$48:B$62) & " Star " & _xlfn.XLOOKUP(G6,A$48:A$62,C$48:C$62) & "%"),_xlfn.XLOOKUP(G6,A$93:A$122,B$93:B$122)),"Not in war") | M6: =IFERROR(IF($E$3=15,IF(_xlfn.XLOOKUP(G6,A$63:A$77,B$63:B$77) = "Missed Hit",_xlfn.XLOOKUP(G6,A$63:A$77,B$63:B$77),_xlfn.XLOOKUP(G6,A$63:A$77,B$63:B$77) & " Star " & _xlfn.XLOOKUP(G6,A$63:A$77,C$63:C$77) & "%"),_xlfn.XLOOKUP(G6,A$123:A$152,B$123:B$152)),"Not in war") | N6: =IFERROR(IF($E$3=15,IF(_xlfn.XLOOKUP(G6,A$78:A$92,B$78:B$92) = "Missed Hit",_xlfn.XLOOKUP(G6,A$78:A$92,B$78:B$92),_xlfn.XLOOKUP(G6,A$78:A$92,B$78:B$92) & " Star " & _xlfn.XLOOKUP(G6,A$78:A$92,C$78:C$92) & "%"),_xlfn.XLOOKUP(G6,A$153:A$182,B$153:B$182)),"Not in war") | O6: =IFERROR(IF($E$3=15,IF(_xlfn.XLOOKUP(G6,A$93:A$107,B$93:B$107) = "Missed Hit",_xlfn.XLOOKUP(G6,A$93:A$107,B$93:B$107),_xlfn.XLOOKUP(G6,A$93:A$107,B$93:B$107) & " Star " & _xlfn.XLOOKUP(G6,A$93:A$107,C$93:C$107) & "%"),_xlfn.XLOOKUP(G6,A$153:A$182,B$153:B$182)),"Not in war") | Q6: =IFERROR($R6/(3*(7-$Y6)),0) | R6: =3*S6+2*T6+U6 | S6: =COUNTIF($I6:$O6, 3 & "*") | T6: =COUNTIF($I6:$O6, 2 & "*") | U6: =COUNTIF($I6:$O6, 1 & "*") | V6: =COUNTIF($I6:$O6, 0 & "*") | W6: =COUNTIF($I6:$O6,"Missed hit") | X6: =IF($E$3=15,SUM(_xlfn.XLOOKUP(G6,$A$3:$A$17,$C$3:$C$17,0),_xlfn.XLOOKUP(G6,$A$18:$A$32,$C$18:$C$32,0),_xlfn.XLOOKUP(G6,$A$33:$A$47,$C$33:$C$47,0), _xlfn.XLOOKUP(G6,$A$48:$A$62,$C$48:$C$62,0), _xlfn.XLOOKUP(G6,$A$63:$A$77,$C$63:$C$77,0), _xlfn.XLOOKUP(G6,$A$78:$A$92,$C$78:$C$92,0), _xlfn.XLOOKUP(G6,$A$93:$A$107,$C$93:$C$107,0))) | Y6: =COUNTIF($I6:$O6,"Not in war") | AB6: 0 | AC6: 0 | AD6: 0 | AE6: 0 | AF6: 0 | AG6: 0 | AH6: 0 | AI6: 0 | AJ6: 0 | AK6: 0 | AL6: 0 | AM6: 0 | AN6: 0 | AO6: 0 | AP6: 0 | AQ6: 0 | AR6: FALSE | AS6: 0
H7: =_xlfn.XLOOKUP(G7,A2:A99,D2:D99) | I7: =IFERROR(IF($E$3=15,IF(_xlfn.XLOOKUP(G7,A$3:A$17,B$3:B$17) = "Missed Hit",_xlfn.XLOOKUP(G7,A$3:A$17,B$3:B$17),_xlfn.XLOOKUP(G7,A$3:A$17,B$3:B$17) & " Star " & _xlfn.XLOOKUP(G7,A$3:A$17,C$3:C$17) & "%"),_xlfn.XLOOKUP(G7,A$3:A$32,B$3:B$32)),"Not in war") | J7: =IFERROR(IF($E$3=15,IF(_xlfn.XLOOKUP(G7,A$18:A$32,B$18:B$32) = "Missed Hit",_xlfn.XLOOKUP(G7,A$18:A$32,B$18:B$32),_xlfn.XLOOKUP(G7,A$18:A$32,B$18:B$32) & " Star " & _xlfn.XLOOKUP(G7,A$18:A$32,C$18:C$32) & "%"),_xlfn.XLOOKUP(G7,A$33:A$62,B$33:B$62)),"Not in war") | K7: =IFERROR(IF($E$3=15,IF(_xlfn.XLOOKUP(G7,A$33:A$47,B$33:B$47) = "Missed Hit",_xlfn.XLOOKUP(G7,A$33:A$47,B$33:B$47),_xlfn.XLOOKUP(G7,A$33:A$47,B$33:B$47) & " Star " & _xlfn.XLOOKUP(G7,A$33:A$47,C$33:C$47) & "%"),_xlfn.XLOOKUP(G7,A$63:A$92,B$63:B$92)),"Not in war") | L7: =IFERROR(IF($E$3=15,IF(_xlfn.XLOOKUP(G7,A$48:A$62,B$48:B$62) = "Missed Hit",_xlfn.XLOOKUP(G7,A$48:A$62,B$48:B$62),_xlfn.XLOOKUP(G7,A$48:A$62,B$48:B$62) & " Star " & _xlfn.XLOOKUP(G7,A$48:A$62,C$48:C$62) & "%"),_xlfn.XLOOKUP(G7,A$93:A$122,B$93:B$122)),"Not in war") | M7: =IFERROR(IF($E$3=15,IF(_xlfn.XLOOKUP(G7,A$63:A$77,B$63:B$77) = "Missed Hit",_xlfn.XLOOKUP(G7,A$63:A$77,B$63:B$77),_xlfn.XLOOKUP(G7,A$63:A$77,B$63:B$77) & " Star " & _xlfn.XLOOKUP(G7,A$63:A$77,C$63:C$77) & "%"),_xlfn.XLOOKUP(G7,A$123:A$152,B$123:B$152)),"Not in war") | N7: =IFERROR(IF($E$3=15,IF(_xlfn.XLOOKUP(G7,A$78:A$92,B$78:B$92) = "Missed Hit",_xlfn.XLOOKUP(G7,A$78:A$92,B$78:B$92),_xlfn.XLOOKUP(G7,A$78:A$92,B$78:B$92) & " Star " & _xlfn.XLOOKUP(G7,A$78:A$92,C$78:C$92) & "%"),_xlfn.XLOOKUP(G7,A$153:A$182,B$153:B$182)),"Not in war") | O7: =IFERROR(IF($E$3=15,IF(_xlfn.XLOOKUP(G7,A$93:A$107,B$93:B$107) = "Missed Hit",_xlfn.XLOOKUP(G7,A$93:A$107,B$93:B$107),_xlfn.XLOOKUP(G7,A$93:A$107,B$93:B$107) & " Star " & _xlfn.XLOOKUP(G7,A$93:A$107,C$93:C$107) & "%"),_xlfn.XLOOKUP(G7,A$153:A$182,B$153:B$182)),"Not in war") | Q7: =IFERROR($R7/(3*(7-$Y7)),0) | R7: =3*S7+2*T7+U7 | S7: =COUNTIF($I7:$O7, 3 & "*") | T7: =COUNTIF($I7:$O7, 2 & "*") | U7: =COUNTIF($I7:$O7, 1 & "*") | V7: =COUNTIF($I7:$O7, 0 & "*") | W7: =COUNTIF($I7:$O7,"Missed hit") | X7: =IF($E$3=15,SUM(_xlfn.XLOOKUP(G7,$A$3:$A$17,$C$3:$C$17,0),_xlfn.XLOOKUP(G7,$A$18:$A$32,$C$18:$C$32,0),_xlfn.XLOOKUP(G7,$A$33:$A$47,$C$33:$C$47,0), _xlfn.XLOOKUP(G7,$A$48:$A$62,$C$48:$C$62,0), _xlfn.XLOOKUP(G7,$A$63:$A$77,$C$63:$C$77,0), _xlfn.XLOOKUP(G7,$A$78:$A$92,$C$78:$C$92,0), _xlfn.XLOOKUP(G7,$A$93:$A$107,$C$93:$C$107,0))) | Y7: =COUNTIF($I7:$O7,"Not in war") | AB7: 0 | AC7: 0 | AD7: 0 | AE7: 0 | AF7: 0 | AG7: 0 | AH7: 0 | AI7: 0 | AJ7: 0 | AK7: 0 | AL7: 0 | AM7: 0 | AN7: 0 | AO7: 0 | AP7: 0 | AQ7: 0 | AR7: FALSE | AS7: 0
H8: =_xlfn.XLOOKUP(G8,A1:A101,D1:D101) | I8: =IFERROR(IF($E$3=15,IF(_xlfn.XLOOKUP(G8,A$3:A$17,B$3:B$17) = "Missed Hit",_xlfn.XLOOKUP(G8,A$3:A$17,B$3:B$17),_xlfn.XLOOKUP(G8,A$3:A$17,B$3:B$17) & " Star " & _xlfn.XLOOKUP(G8,A$3:A$17,C$3:C$17) & "%"),_xlfn.XLOOKUP(G8,A$3:A$32,B$3:B$32)),"Not in war") | J8: =IFERROR(IF($E$3=15,IF(_xlfn.XLOOKUP(G8,A$18:A$32,B$18:B$32) = "Missed Hit",_xlfn.XLOOKUP(G8,A$18:A$32,B$18:B$32),_xlfn.XLOOKUP(G8,A$18:A$32,B$18:B$32) & " Star " & _xlfn.XLOOKUP(G8,A$18:A$32,C$18:C$32) & "%"),_xlfn.XLOOKUP(G8,A$33:A$62,B$33:B$62)),"Not in war") | K8: =IFERROR(IF($E$3=15,IF(_xlfn.XLOOKUP(G8,A$33:A$47,B$33:B$47) = "Missed Hit",_xlfn.XLOOKUP(G8,A$33:A$47,B$33:B$47),_xlfn.XLOOKUP(G8,A$33:A$47,B$33:B$47) & " Star " & _xlfn.XLOOKUP(G8,A$33:A$47,C$33:C$47) & "%"),_xlfn.XLOOKUP(G8,A$63:A$92,B$63:B$92)),"Not in war") | L8: =IFERROR(IF($E$3=15,IF(_xlfn.XLOOKUP(G8,A$48:A$62,B$48:B$62) = "Missed Hit",_xlfn.XLOOKUP(G8,A$48:A$62,B$48:B$62),_xlfn.XLOOKUP(G8,A$48:A$62,B$48:B$62) & " Star " & _xlfn.XLOOKUP(G8,A$48:A$62,C$48:C$62) & "%"),_xlfn.XLOOKUP(G8,A$93:A$122,B$93:B$122)),"Not in war") | M8: =IFERROR(IF($E$3=15,IF(_xlfn.XLOOKUP(G8,A$63:A$77,B$63:B$77) = "Missed Hit",_xlfn.XLOOKUP(G8,A$63:A$77,B$63:B$77),_xlfn.XLOOKUP(G8,A$63:A$77,B$63:B$77) & " Star " & _xlfn.XLOOKUP(G8,A$63:A$77,C$63:C$77) & "%"),_xlfn.XLOOKUP(G8,A$123:A$152,B$123:B$152)),"Not in war") | N8: =IFERROR(IF($E$3=15,IF(_xlfn.XLOOKUP(G8,A$78:A$92,B$78:B$92) = "Missed Hit",_xlfn.XLOOKUP(G8,A$78:A$92,B$78:B$92),_xlfn.XLOOKUP(G8,A$78:A$92,B$78:B$92) & " Star " & _xlfn.XLOOKUP(G8,A$78:A$92,C$78:C$92) & "%"),_xlfn.XLOOKUP(G8,A$153:A$182,B$153:B$182)),"Not in war") | O8: =IFERROR(IF($E$3=15,IF(_xlfn.XLOOKUP(G8,A$93:A$107,B$93:B$107) = "Missed Hit",_xlfn.XLOOKUP(G8,A$93:A$107,B$93:B$107),_xlfn.XLOOKUP(G8,A$93:A$107,B$93:B$107) & " Star " & _xlfn.XLOOKUP(G8,A$93:A$107,C$93:C$107) & "%"),_xlfn.XLOOKUP(G8,A$153:A$182,B$153:B$182)),"Not in war") | Q8: =IFERROR($R8/(3*(7-$Y8)),0) | R8: =3*S8+2*T8+U8 | S8: =COUNTIF($I8:$O8, 3 & "*") | T8: =COUNTIF($I8:$O8, 2 & "*") | U8: =COUNTIF($I8:$O8, 1 & "*") | V8: =COUNTIF($I8:$O8, 0 & "*") | W8: =COUNTIF($I8:$O8,"Missed hit") | X8: =IF($E$3=15,SUM(_xlfn.XLOOKUP(G8,$A$3:$A$17,$C$3:$C$17,0),_xlfn.XLOOKUP(G8,$A$18:$A$32,$C$18:$C$32,0),_xlfn.XLOOKUP(G8,$A$33:$A$47,$C$33:$C$47,0), _xlfn.XLOOKUP(G8,$A$48:$A$62,$C$48:$C$62,0), _xlfn.XLOOKUP(G8,$A$63:$A$77,$C$63:$C$77,0), _xlfn.XLOOKUP(G8,$A$78:$A$92,$C$78:$C$92,0), _xlfn.XLOOKUP(G8,$A$93:$A$107,$C$93:$C$107,0))) | Y8: =COUNTIF($I8:$O8,"Not in war") | AB8: 0 | AC8: 0 | AD8: 0 | AE8: 0 | AF8: 0 | AG8: 0 | AH8: 0 | AI8: 0 | AJ8: 0 | AK8: 0 | AL8: 0 | AM8: 0 | AN8: 0 | AO8: 0 | AP8: 0 | AQ8: 0 | AR8: FALSE | AS8: 0
H9: =_xlfn.XLOOKUP(G9,A1:A99,D1:D99) | I9: =IFERROR(IF($E$3=15,IF(_xlfn.XLOOKUP(G9,A$3:A$17,B$3:B$17) = "Missed Hit",_xlfn.XLOOKUP(G9,A$3:A$17,B$3:B$17),_xlfn.XLOOKUP(G9,A$3:A$17,B$3:B$17) & " Star " & _xlfn.XLOOKUP(G9,A$3:A$17,C$3:C$17) & "%"),_xlfn.XLOOKUP(G9,A$3:A$32,B$3:B$32)),"Not in war") | J9: =IFERROR(IF($E$3=15,IF(_xlfn.XLOOKUP(G9,A$18:A$32,B$18:B$32) = "Missed Hit",_xlfn.XLOOKUP(G9,A$18:A$32,B$18:B$32),_xlfn.XLOOKUP(G9,A$18:A$32,B$18:B$32) & " Star " & _xlfn.XLOOKUP(G9,A$18:A$32,C$18:C$32) & "%"),_xlfn.XLOOKUP(G9,A$33:A$62,B$33:B$62)),"Not in war") | K9: =IFERROR(IF($E$3=15,IF(_xlfn.XLOOKUP(G9,A$33:A$47,B$33:B$47) = "Missed Hit",_xlfn.XLOOKUP(G9,A$33:A$47,B$33:B$47),_xlfn.XLOOKUP(G9,A$33:A$47,B$33:B$47) & " Star " & _xlfn.XLOOKUP(G9,A$33:A$47,C$33:C$47) & "%"),_xlfn.XLOOKUP(G9,A$63:A$92,B$63:B$92)),"Not in war") | L9: =IFERROR(IF($E$3=15,IF(_xlfn.XLOOKUP(G9,A$48:A$62,B$48:B$62) = "Missed Hit",_xlfn.XLOOKUP(G9,A$48:A$62,B$48:B$62),_xlfn.XLOOKUP(G9,A$48:A$62,B$48:B$62) & " Star " & _xlfn.XLOOKUP(G9,A$48:A$62,C$48:C$62) & "%"),_xlfn.XLOOKUP(G9,A$93:A$122,B$93:B$122)),"Not in war") | M9: =IFERROR(IF($E$3=15,IF(_xlfn.XLOOKUP(G9,A$63:A$77,B$63:B$77) = "Missed Hit",_xlfn.XLOOKUP(G9,A$63:A$77,B$63:B$77),_xlfn.XLOOKUP(G9,A$63:A$77,B$63:B$77) & " Star " & _xlfn.XLOOKUP(G9,A$63:A$77,C$63:C$77) & "%"),_xlfn.XLOOKUP(G9,A$123:A$152,B$123:B$152)),"Not in war") | N9: =IFERROR(IF($E$3=15,IF(_xlfn.XLOOKUP(G9,A$78:A$92,B$78:B$92) = "Missed Hit",_xlfn.XLOOKUP(G9,A$78:A$92,B$78:B$92),_xlfn.XLOOKUP(G9,A$78:A$92,B$78:B$92) & " Star " & _xlfn.XLOOKUP(G9,A$78:A$92,C$78:C$92) & "%"),_xlfn.XLOOKUP(G9,A$153:A$182,B$153:B$182)),"Not in war") | O9: =IFERROR(IF($E$3=15,IF(_xlfn.XLOOKUP(G9,A$93:A$107,B$93:B$107) = "Missed Hit",_xlfn.XLOOKUP(G9,A$93:A$107,B$93:B$107),_xlfn.XLOOKUP(G9,A$93:A$107,B$93:B$107) & " Star " & _xlfn.XLOOKUP(G9,A$93:A$107,C$93:C$107) & "%"),_xlfn.XLOOKUP(G9,A$153:A$182,B$153:B$182)),"Not in war") | Q9: =IFERROR($R9/(3*(7-$Y9)),0) | R9: =3*S9+2*T9+U9 | S9: =COUNTIF($I9:$O9, 3 & "*") | T9: =COUNTIF($I9:$O9, 2 & "*") | U9: =COUNTIF($I9:$O9, 1 & "*") | V9: =COUNTIF($I9:$O9, 0 & "*") | W9: =COUNTIF($I9:$O9,"Missed hit") | X9: =IF($E$3=15,SUM(_xlfn.XLOOKUP(G9,$A$3:$A$17,$C$3:$C$17,0),_xlfn.XLOOKUP(G9,$A$18:$A$32,$C$18:$C$32,0),_xlfn.XLOOKUP(G9,$A$33:$A$47,$C$33:$C$47,0), _xlfn.XLOOKUP(G9,$A$48:$A$62,$C$48:$C$62,0), _xlfn.XLOOKUP(G9,$A$63:$A$77,$C$63:$C$77,0), _xlfn.XLOOKUP(G9,$A$78:$A$92,$C$78:$C$92,0), _xlfn.XLOOKUP(G9,$A$93:$A$107,$C$93:$C$107,0))) | Y9: =COUNTIF($I9:$O9,"Not in war") | AB9: 0 | AC9: 0 | AD9: 0 | AE9: 0 | AF9: 0 | AG9: 0 | AH9: 0 | AI9: 0 | AJ9: 0 | AK9: 0 | AL9: 0 | AM9: 0 | AN9: 0 | AO9: 0 | AP9: 0 | AQ9: 0 | AR9: FALSE | AS9: 0
H10: =_xlfn.XLOOKUP(G10,A3:A107,D3:D107) | I10: =IFERROR(IF($E$3=15,IF(_xlfn.XLOOKUP(G10,A$3:A$17,B$3:B$17) = "Missed Hit",_xlfn.XLOOKUP(G10,A$3:A$17,B$3:B$17),_xlfn.XLOOKUP(G10,A$3:A$17,B$3:B$17) & " Star " & _xlfn.XLOOKUP(G10,A$3:A$17,C$3:C$17) & "%"),_xlfn.XLOOKUP(G10,A$3:A$32,B$3:B$32)),"Not in war") | J10: =IFERROR(IF($E$3=15,IF(_xlfn.XLOOKUP(G10,A$18:A$32,B$18:B$32) = "Missed Hit",_xlfn.XLOOKUP(G10,A$18:A$32,B$18:B$32),_xlfn.XLOOKUP(G10,A$18:A$32,B$18:B$32) & " Star " & _xlfn.XLOOKUP(G10,A$18:A$32,C$18:C$32) & "%"),_xlfn.XLOOKUP(G10,A$33:A$62,B$33:B$62)),"Not in war") | K10: =IFERROR(IF($E$3=15,IF(_xlfn.XLOOKUP(G10,A$33:A$47,B$33:B$47) = "Missed Hit",_xlfn.XLOOKUP(G10,A$33:A$47,B$33:B$47),_xlfn.XLOOKUP(G10,A$33:A$47,B$33:B$47) & " Star " & _xlfn.XLOOKUP(G10,A$33:A$47,C$33:C$47) & "%"),_xlfn.XLOOKUP(G10,A$63:A$92,B$63:B$92)),"Not in war") | L10: =IFERROR(IF($E$3=15,IF(_xlfn.XLOOKUP(G10,A$48:A$62,B$48:B$62) = "Missed Hit",_xlfn.XLOOKUP(G10,A$48:A$62,B$48:B$62),_xlfn.XLOOKUP(G10,A$48:A$62,B$48:B$62) & " Star " & _xlfn.XLOOKUP(G10,A$48:A$62,C$48:C$62) & "%"),_xlfn.XLOOKUP(G10,A$93:A$122,B$93:B$122)),"Not in war") | M10: =IFERROR(IF($E$3=15,IF(_xlfn.XLOOKUP(G10,A$63:A$77,B$63:B$77) = "Missed Hit",_xlfn.XLOOKUP(G10,A$63:A$77,B$63:B$77),_xlfn.XLOOKUP(G10,A$63:A$77,B$63:B$77) & " Star " & _xlfn.XLOOKUP(G10,A$63:A$77,C$63:C$77) & "%"),_xlfn.XLOOKUP(G10,A$123:A$152,B$123:B$152)),"Not in war") | N10: =IFERROR(IF($E$3=15,IF(_xlfn.XLOOKUP(G10,A$78:A$92,B$78:B$92) = "Missed Hit",_xlfn.XLOOKUP(G10,A$78:A$92,B$78:B$92),_xlfn.XLOOKUP(G10,A$78:A$92,B$78:B$92) & " Star " & _xlfn.XLOOKUP(G10,A$78:A$92,C$78:C$92) & "%"),_xlfn.XLOOKUP(G10,A$153:A$182,B$153:B$182)),"Not in war") | O10: =IFERROR(IF($E$3=15,IF(_xlfn.XLOOKUP(G10,A$93:A$107,B$93:B$107) = "Missed Hit",_xlfn.XLOOKUP(G10,A$93:A$107,B$93:B$107),_xlfn.XLOOKUP(G10,A$93:A$107,B$93:B$107) & " Star " & _xlfn.XLOOKUP(G10,A$93:A$107,C$93:C$107) & "%"),_xlfn.XLOOKUP(G10,A$153:A$182,B$153:B$182)),"Not in war") | Q10: =IFERROR($R10/(3*(7-$Y10)),0) | R10: =3*S10+2*T10+U10 | S10: =COUNTIF($I10:$O10, 3 & "*") | T10: =COUNTIF($I10:$O10, 2 & "*") | U10: =COUNTIF($I10:$O10, 1 & "*") | V10: =COUNTIF($I10:$O10, 0 & "*") | W10: =COUNTIF($I10:$O10,"Missed hit") | X10: =IF($E$3=15,SUM(_xlfn.XLOOKUP(G10,$A$3:$A$17,$C$3:$C$17,0),_xlfn.XLOOKUP(G10,$A$18:$A$32,$C$18:$C$32,0),_xlfn.XLOOKUP(G10,$A$33:$A$47,$C$33:$C$47,0), _xlfn.XLOOKUP(G10,$A$48:$A$62,$C$48:$C$62,0), _xlfn.XLOOKUP(G10,$A$63:$A$77,$C$63:$C$77,0), _xlfn.XLOOKUP(G10,$A$78:$A$92,$C$78:$C$92,0), _xlfn.XLOOKUP(G10,$A$93:$A$107,$C$93:$C$107,0))) | Y10: =COUNTIF($I10:$O10,"Not in war") | AB10: 0 | AC10: 0 | AD10: 0 | AE10: 0 | AF10: 0 | AG10: 0 | AH10: 0 | AI10: 0 | AJ10: 0 | AK10: 0 | AL10: 0 | AM10: 0 | AN10: 0 | AO10: 0 | AP10: 0 | AQ10: 0 | AR10: FALSE | AS10: 0
H11: =_xlfn.XLOOKUP(G11,A9:A109,D9:D109) | I11: =IFERROR(IF($E$3=15,IF(_xlfn.XLOOKUP(G11,A$3:A$17,B$3:B$17) = "Missed Hit",_xlfn.XLOOKUP(G11,A$3:A$17,B$3:B$17),_xlfn.XLOOKUP(G11,A$3:A$17,B$3:B$17) & " Star " & _xlfn.XLOOKUP(G11,A$3:A$17,C$3:C$17) & "%"),_xlfn.XLOOKUP(G11,A$3:A$32,B$3:B$32)),"Not in war") | J11: =IFERROR(IF($E$3=15,IF(_xlfn.XLOOKUP(G11,A$18:A$32,B$18:B$32) = "Missed Hit",_xlfn.XLOOKUP(G11,A$18:A$32,B$18:B$32),_xlfn.XLOOKUP(G11,A$18:A$32,B$18:B$32) & " Star " & _xlfn.XLOOKUP(G11,A$18:A$32,C$18:C$32) & "%"),_xlfn.XLOOKUP(G11,A$33:A$62,B$33:B$62)),"Not in war") | K11: =IFERROR(IF($E$3=15,IF(_xlfn.XLOOKUP(G11,A$33:A$47,B$33:B$47) = "Missed Hit",_xlfn.XLOOKUP(G11,A$33:A$47,B$33:B$47),_xlfn.XLOOKUP(G11,A$33:A$47,B$33:B$47) & " Star " & _xlfn.XLOOKUP(G11,A$33:A$47,C$33:C$47) & "%"),_xlfn.XLOOKUP(G11,A$63:A$92,B$63:B$92)),"Not in war") | L11: =IFERROR(IF($E$3=15,IF(_xlfn.XLOOKUP(G11,A$48:A$62,B$48:B$62) = "Missed Hit",_xlfn.XLOOKUP(G11,A$48:A$62,B$48:B$62),_xlfn.XLOOKUP(G11,A$48:A$62,B$48:B$62) & " Star " & _xlfn.XLOOKUP(G11,A$48:A$62,C$48:C$62) & "%"),_xlfn.XLOOKUP(G11,A$93:A$122,B$93:B$122)),"Not in war") | M11: =IFERROR(IF($E$3=15,IF(_xlfn.XLOOKUP(G11,A$63:A$77,B$63:B$77) = "Missed Hit",_xlfn.XLOOKUP(G11,A$63:A$77,B$63:B$77),_xlfn.XLOOKUP(G11,A$63:A$77,B$63:B$77) & " Star " & _xlfn.XLOOKUP(G11,A$63:A$77,C$63:C$77) & "%"),_xlfn.XLOOKUP(G11,A$123:A$152,B$123:B$152)),"Not in war") | N11: =IFERROR(IF($E$3=15,IF(_xlfn.XLOOKUP(G11,A$78:A$92,B$78:B$92) = "Missed Hit",_xlfn.XLOOKUP(G11,A$78:A$92,B$78:B$92),_xlfn.XLOOKUP(G11,A$78:A$92,B$78:B$92) & " Star " & _xlfn.XLOOKUP(G11,A$78:A$92,C$78:C$92) & "%"),_xlfn.XLOOKUP(G11,A$153:A$182,B$153:B$182)),"Not in war") | O11: =IFERROR(IF($E$3=15,IF(_xlfn.XLOOKUP(G11,A$93:A$107,B$93:B$107) = "Missed Hit",_xlfn.XLOOKUP(G11,A$93:A$107,B$93:B$107),_xlfn.XLOOKUP(G11,A$93:A$107,B$93:B$107) & " Star " & _xlfn.XLOOKUP(G11,A$93:A$107,C$93:C$107) & "%"),_xlfn.XLOOKUP(G11,A$153:A$182,B$153:B$182)),"Not in war") | Q11: =IFERROR($R11/(3*(7-$Y11)),0) | R11: =3*S11+2*T11+U11 | S11: =COUNTIF($I11:$O11, 3 & "*") | T11: =COUNTIF($I11:$O11, 2 & "*") | U11: =COUNTIF($I11:$O11, 1 & "*") | V11: =COUNTIF($I11:$O11, 0 & "*") | W11: =COUNTIF($I11:$O11,"Missed hit") | X11: =IF($E$3=15,SUM(_xlfn.XLOOKUP(G11,$A$3:$A$17,$C$3:$C$17,0),_xlfn.XLOOKUP(G11,$A$18:$A$32,$C$18:$C$32,0),_xlfn.XLOOKUP(G11,$A$33:$A$47,$C$33:$C$47,0), _xlfn.XLOOKUP(G11,$A$48:$A$62,$C$48:$C$62,0), _xlfn.XLOOKUP(G11,$A$63:$A$77,$C$63:$C$77,0), _xlfn.XLOOKUP(G11,$A$78:$A$92,$C$78:$C$92,0), _xlfn.XLOOKUP(G11,$A$93:$A$107,$C$93:$C$107,0))) | Y11: =COUNTIF($I11:$O11,"Not in war") | AB11: 0 | AC11: 0 | AD11: 0 | AE11: 0 | AF11: 0 | AG11: 0 | AH11: 0 | AI11: 0 | AJ11: 0 | AK11: 0 | AL11: 0 | AM11: 0 | AN11: 0 | AO11: 0 | AP11: 0 | AQ11: 0 | AR11: FALSE | AS11: 0
